Workbook

Sheet สรุปผล
A1: KU Lost & Found — ผลทดสอบตาม TEST_PLAN, TEST_CASES และ USER_MANUAL
A3: วันที่ทดสอบ | B3: 25/10/2026
A4: ผู้ทดสอบ | B4: Claude (รันตาม TEST_PLAN)
A5: เอกสารอ้างอิง | B5: docs/TEST_PLAN.md, docs/TEST_CASES.md (436 กรณี), docs/USER_MANUAL.md
A6: สภาพแวดล้อม | B6: Windows 10, Node 24, PostgreSQL 16 (localhost:5432), Microsoft Edge; ฐานทดสอบแยก (PGlite / ฐานชั่วคราว) + ตรวจฐานจริงแบบอ่านอย่างเดียว
A7: หลักฐานดิบ | B7: output/auto-test/2026-10-25T10-18-57-044Z-3739a5
A10: 1) Test Cases ตามเอกสาร (docs/TEST_CASES.md)
A11: กลุ่ม | B11: ทั้งหมด | C11: Pass | D11: Fail | E11: Fail (TODO) | F11: Blocked | G11: Not Run | H11: % ผ่าน
A12: Unit/Integration (PGlite) | B12: =COUNTIF('Test Cases (เอกสาร)'!$A:$A,"UNIT-*") -> 134 | C12: =COUNTIFS('Test Cases (เอกสาร)'!$A:$A,"UNIT-*",'Test Cases (เอกสาร)'!$J:$J,"Pass") -> 132 | D12: =COUNTIFS('Test Cases (เอกสาร)'!$A:$A,"UNIT-*",'Test Cases (เอกสาร)'!$J:$J,"Fail") -> 0 | E12: =COUNTIFS('Test Cases (เอกสาร)'!$A:$A,"UNIT-*",'Test Cases (เอกสาร)'!$J:$J,"Fail (TODO)") -> 0 | F12: =COUNTIFS('Test Cases (เอกสาร)'!$A:$A,"UNIT-*",'Test Cases (เอกสาร)'!$J:$J,"Blocked") -> 0 | G12: =COUNTIFS('Test Cases (เอกสาร)'!$A:$A,"UNIT-*",'Test Cases (เอกสาร)'!$J:$J,"Not Run") -> 2 | H12: =IF((C12+D12+E12)=0,"-",C12/(C12+D12+E12)) -> 1
A13: สิทธิ์ตามบทบาท/API | B13: =COUNTIF('Test Cases (เอกสาร)'!$A:$A,"ROLE-*") -> 106 | C13: =COUNTIFS('Test Cases (เอกสาร)'!$A:$A,"ROLE-*",'Test Cases (เอกสาร)'!$J:$J,"Pass") -> 106 | D13: =COUNTIFS('Test Cases (เอกสาร)'!$A:$A,"ROLE-*",'Test Cases (เอกสาร)'!$J:$J,"Fail") -> 0 | E13: =COUNTIFS('Test Cases (เอกสาร)'!$A:$A,"ROLE-*",'Test Cases (เอกสาร)'!$J:$J,"Fail (TODO)") -> 0 | F13: =COUNTIFS('Test Cases (เอกสาร)'!$A:$A,"ROLE-*",'Test Cases (เอกสาร)'!$J:$J,"Blocked") -> 0 | G13: =COUNTIFS('Test Cases (เอกสาร)'!$A:$A,"ROLE-*",'Test Cases (เอกสาร)'!$J:$J,"Not Run") -> 0 | H13: =IF((C13+D13+E13)=0,"-",C13/(C13+D13+E13)) -> 1
A14: PostgreSQL จริง (ฐานชั่วคราว) | B14: =COUNTIF('Test Cases (เอกสาร)'!$A:$A,"PG-*")-COUNTIF('Test Cases (เอกสาร)'!$A:$A,"PG-OP-*") -> 37 | C14: =COUNTIFS('Test Cases (เอกสาร)'!$A:$A,"PG-*",'Test Cases (เอกสาร)'!$J:$J,"Pass")-COUNTIFS('Test Cases (เอกสาร)'!$A:$A,"PG-OP-*",'Test Cases (เอกสาร)'!$J:$J,"Pass") -> 37 | D14: =COUNTIFS('Test Cases (เอกสาร)'!$A:$A,"PG-*",'Test Cases (เอกสาร)'!$J:$J,"Fail")-COUNTIFS('Test Cases (เอกสาร)'!$A:$A,"PG-OP-*",'Test Cases (เอกสาร)'!$J:$J,"Fail") -> 0 | E14: =COUNTIFS('Test Cases (เอกสาร)'!$A:$A,"PG-*",'Test Cases (เอกสาร)'!$J:$J,"Fail (TODO)")-COUNTIFS('Test Cases (เอกสาร)'!$A:$A,"PG-OP-*",'Test Cases (เอกสาร)'!$J:$J,"Fail (TODO)") -> 0 | F14: =COUNTIFS('Test Cases (เอกสาร)'!$A:$A,"PG-*",'Test Cases (เอกสาร)'!$J:$J,"Blocked")-COUNTIFS('Test Cases (เอกสาร)'!$A:$A,"PG-OP-*",'Test Cases (เอกสาร)'!$J:$J,"Blocked") -> 0 | G14: =COUNTIFS('Test Cases (เอกสาร)'!$A:$A,"PG-*",'Test Cases (เอกสาร)'!$J:$J,"Not Run")-COUNTIFS('Test Cases (เอกสาร)'!$A:$A,"PG-OP-*",'Test Cases (เอกสาร)'!$J:$J,"Not Run") -> 0 | H14: =IF((C14+D14+E14)=0,"-",C14/(C14+D14+E14)) -> 1
A15: เริ่มระบบเต็ม + PostgreSQL | B15: =COUNTIF('Test Cases (เอกสาร)'!$A:$A,"PG-OP-*") -> 3 | C15: =COUNTIFS('Test Cases (เอกสาร)'!$A:$A,"PG-OP-*",'Test Cases (เอกสาร)'!$J:$J,"Pass") -> 3 | D15: =COUNTIFS('Test Cases (เอกสาร)'!$A:$A,"PG-OP-*",'Test Cases (เอกสาร)'!$J:$J,"Fail") -> 0 | E15: =COUNTIFS('Test Cases (เอกสาร)'!$A:$A,"PG-OP-*",'Test Cases (เอกสาร)'!$J:$J,"Fail (TODO)") -> 0 | F15: =COUNTIFS('Test Cases (เอกสาร)'!$A:$A,"PG-OP-*",'Test Cases (เอกสาร)'!$J:$J,"Blocked") -> 0 | G15: =COUNTIFS('Test Cases (เอกสาร)'!$A:$A,"PG-OP-*",'Test Cases (เอกสาร)'!$J:$J,"Not Run") -> 0 | H15: =IF((C15+D15+E15)=0,"-",C15/(C15+D15+E15)) -> 1
A16: หน้าเว็บ (Playwright/Edge) | B16: =COUNTIF('Test Cases (เอกสาร)'!$A:$A,"WEB-*") -> 122 | C16: =COUNTIFS('Test Cases (เอกสาร)'!$A:$A,"WEB-*",'Test Cases (เอกสาร)'!$J:$J,"Pass") -> 122 | D16: =COUNTIFS('Test Cases (เอกสาร)'!$A:$A,"WEB-*",'Test Cases (เอกสาร)'!$J:$J,"Fail") -> 0 | E16: =COUNTIFS('Test Cases (เอกสาร)'!$A:$A,"WEB-*",'Test Cases (เอกสาร)'!$J:$J,"Fail (TODO)") -> 0 | F16: =COUNTIFS('Test Cases (เอกสาร)'!$A:$A,"WEB-*",'Test Cases (เอกสาร)'!$J:$J,"Blocked") -> 0 | G16: =COUNTIFS('Test Cases (เอกสาร)'!$A:$A,"WEB-*",'Test Cases (เอกสาร)'!$J:$J,"Not Run") -> 0 | H16: =IF((C16+D16+E16)=0,"-",C16/(C16+D16+E16)) -> 1
A17: ระบบในเครื่อง (อ่านอย่างเดียว) | B17: =COUNTIF('Test Cases (เอกสาร)'!$A:$A,"OP-*") -> 21 | C17: =COUNTIFS('Test Cases (เอกสาร)'!$A:$A,"OP-*",'Test Cases (เอกสาร)'!$J:$J,"Pass") -> 19 | D17: =COUNTIFS('Test Cases (เอกสาร)'!$A:$A,"OP-*",'Test Cases (เอกสาร)'!$J:$J,"Fail") -> 2 | E17: =COUNTIFS('Test Cases (เอกสาร)'!$A:$A,"OP-*",'Test Cases (เอกสาร)'!$J:$J,"Fail (TODO)") -> 0 | F17: =COUNTIFS('Test Cases (เอกสาร)'!$A:$A,"OP-*",'Test Cases (เอกสาร)'!$J:$J,"Blocked") -> 0 | G17: =COUNTIFS('Test Cases (เอกสาร)'!$A:$A,"OP-*",'Test Cases (เอกสาร)'!$J:$J,"Not Run") -> 0 | H17: =IF((C17+D17+E17)=0,"-",C17/(C17+D17+E17)) -> 0.9047619
A18: Static/Build/Dependency | B18: =COUNTIF('Test Cases (เอกสาร)'!$A:$A,"QA-*") -> 5 | C18: =COUNTIFS('Test Cases (เอกสาร)'!$A:$A,"QA-*",'Test Cases (เอกสาร)'!$J:$J,"Pass") -> 5 | D18: =COUNTIFS('Test Cases (เอกสาร)'!$A:$A,"QA-*",'Test Cases (เอกสาร)'!$J:$J,"Fail") -> 0 | E18: =COUNTIFS('Test Cases (เอกสาร)'!$A:$A,"QA-*",'Test Cases (เอกสาร)'!$J:$J,"Fail (TODO)") -> 0 | F18: =COUNTIFS('Test Cases (เอกสาร)'!$A:$A,"QA-*",'Test Cases (เอกสาร)'!$J:$J,"Blocked") -> 0 | G18: =COUNTIFS('Test Cases (เอกสาร)'!$A:$A,"QA-*",'Test Cases (เอกสาร)'!$J:$J,"Not Run") -> 0 | H18: =IF((C18+D18+E18)=0,"-",C18/(C18+D18+E18)) -> 1
A19: ภายนอก/ต้องใช้คนหรือ production | B19: =COUNTIF('Test Cases (เอกสาร)'!$A:$A,"EXT-*") -> 8 | C19: =COUNTIFS('Test Cases (เอกสาร)'!$A:$A,"EXT-*",'Test Cases (เอกสาร)'!$J:$J,"Pass") -> 0 | D19: =COUNTIFS('Test Cases (เอกสาร)'!$A:$A,"EXT-*",'Test Cases (เอกสาร)'!$J:$J,"Fail") -> 0 | E19: =COUNTIFS('Test Cases (เอกสาร)'!$A:$A,"EXT-*",'Test Cases (เอกสาร)'!$J:$J,"Fail (TODO)") -> 0 | F19: =COUNTIFS('Test Cases (เอกสาร)'!$A:$A,"EXT-*",'Test Cases (เอกสาร)'!$J:$J,"Blocked") -> 5 | G19: =COUNTIFS('Test Cases (เอกสาร)'!$A:$A,"EXT-*",'Test Cases (เอกสาร)'!$J:$J,"Not Run") -> 3 | H19: =IF((C19+D19+E19)=0,"-",C19/(C19+D19+E19)) -> -
A20: รวม | B20: =SUM(B12:B19) -> 436 | C20: =SUM(C12:C19) -> 424 | D20: =SUM(D12:D19) -> 2 | E20: =SUM(E12:E19) -> 0 | F20: =SUM(F12:F19) -> 5 | G20: =SUM(G12:G19) -> 5 | H20: =IF((C20+D20+E20)=0,"-",C20/(C20+D20+E20)) -> 0.99530516
A22: 2) เดินตามคู่มือผู้ใช้ (docs/USER_MANUAL.md)
A23: กลุ่ม | B23: ทั้งหมด | C23: Pass | D23: Fail | E23: Fail (TODO) | F23: Blocked | G23: Not Run | H23: % ผ่าน
A24: ทุกขั้นตอนในคู่มือ | B24: =COUNTIF('User Manual'!$A:$A,"UM-*") -> 19 | C24: =COUNTIFS('User Manual'!$A:$A,"UM-*",'User Manual'!$G:$G,"Pass") -> 16 | D24: =COUNTIFS('User Manual'!$A:$A,"UM-*",'User Manual'!$G:$G,"Fail") -> 2 | E24: =COUNTIFS('User Manual'!$A:$A,"UM-*",'User Manual'!$G:$G,"Fail (TODO)") -> 0 | F24: =COUNTIFS('User Manual'!$A:$A,"UM-*",'User Manual'!$G:$G,"Blocked") -> 0 | G24: =COUNTIFS('User Manual'!$A:$A,"UM-*",'User Manual'!$G:$G,"Not Run") -> 1 | H24: =IF((C24+D24+E24)=0,"-",C24/(C24+D24+E24)) -> 0.88888889
A25: รวม | B25: =SUM(B24:B24) -> 19 | C25: =SUM(C24:C24) -> 16 | D25: =SUM(D24:D24) -> 2 | E25: =SUM(E24:E24) -> 0 | F25: =SUM(F24:F24) -> 0 | G25: =SUM(G24:G24) -> 1 | H25: =IF((C25+D25+E25)=0,"-",C25/(C25+D25+E25)) -> 0.88888889
A27: คู่มือไม่ตรงกับหน้าจอ (ทั้งหมด/บางส่วน) | B27: =COUNTIF('User Manual'!$H:$H,"ไม่ตรง*")+COUNTIF('User Manual'!$H:$H,"ตรงบางส่วน*") -> 9
A29: เปรียบเทียบกับผลในเอกสาร (21 ต.ค.)
A30: เดิม Fail → รอบนี้ Pass | B30: =COUNTIFS('Test Cases (เอกสาร)'!$K:$K,"Fail",'Test Cases (เอกสาร)'!$J:$J,"Pass") -> 17
A31: เดิม Pass → รอบนี้ไม่ Pass | B31: =COUNTIFS('Test Cases (เอกสาร)'!$K:$K,"Pass",'Test Cases (เอกสาร)'!$J:$J,"<>Pass") -> 1
A32: เดิม Fail → ยัง Fail | B32: =COUNTIFS('Test Cases (เอกสาร)'!$K:$K,"Fail",'Test Cases (เอกสาร)'!$J:$J,"Fail") -> 1
A34: % ผ่าน = Pass ÷ (Pass + Fail + Fail (TODO)) ของกรณีที่รันได้ ไม่ใช่เปอร์เซ็นต์ความครบของ requirements หรือความแม่นยำของ AI (ตาม TEST_PLAN)

Sheet Test Cases (เอกสาร)
A1: รหัสกรณี | B1: กลุ่ม | C1: ฟังก์ชัน / สถานการณ์ | D1: ส่วนงาน / ไฟล์ทดสอบ | E1: เงื่อนไขก่อนทดสอบ | F1: ขั้นตอน | G1: ข้อมูลทดสอบ | H1: ผลที่คาดหวัง | I1: ผลจริง (25 ต.ค. 2569) | J1: สถานะ (รอบนี้) | K1: สถานะในเอกสาร (21 ต.ค.) | L1: ความรุนแรง/ความสำคัญ | M1: รหัสบั๊ก | N1: หลักฐาน | O1: ผู้ทดสอบ | P1: วันที่
A2: UNIT-001 | B2: Unit/Integration (PGlite) | C2: ตรวจพิกัด: ยอมรับค่า 0 และค่าขอบเขต แต่ปฏิเสธพิกัดผิดรูปแบบหรือระบุไม่ครบคู่ | D2: การทดสอบหน่วยและระบบร่วม — test/audit-regression.test.cjs | E2: ใช้ฐานจำลอง PGlite แยกจากข้อมูลจริง พร้อมการย้ายโครงสร้างและเตรียมข้อมูลตามไฟล์ทดสอบ | F2: รันกรณีทดสอบอัตโนมัติที่อ้างอิง ตรวจเงื่อนไขยืนยันผล โดยไม่เปลี่ยนผลที่คาดหวัง | G2: ข้อมูลสังเคราะห์เท่านั้น ค่าป้อนและค่าขอบเขตแต่ละรายการอยู่ในตัวกรณีทดสอบของไฟล์ที่อ้างอิง | H2: ตรวจพิกัด: ยอมรับค่า 0 และค่าขอบเขต แต่ปฏิเสธพิกัดผิดรูปแบบหรือระบุไม่ครบคู่ | I2: assertion ผ่านทั้งหมด | J2: Pass | K2: Pass | L2: ปานกลาง/P2 | N2: unit.log | O2: Claude (รันตาม TEST_PLAN) | P2: 46320
A3: UNIT-002 | B3: Unit/Integration (PGlite) | C3: ตรวจช่วงวันที่: ปฏิเสธวันที่ไม่มีจริงและช่วงที่วันสิ้นสุดอยู่ก่อนวันเริ่มต้น | D3: การทดสอบหน่วยและระบบร่วม — test/audit-regression.test.cjs | E3: ใช้ฐานจำลอง PGlite แยกจากข้อมูลจริง พร้อมการย้ายโครงสร้างและเตรียมข้อมูลตามไฟล์ทดสอบ | F3: รันกรณีทดสอบอัตโนมัติที่อ้างอิง ตรวจเงื่อนไขยืนยันผล โดยไม่เปลี่ยนผลที่คาดหวัง | G3: ข้อมูลสังเคราะห์เท่านั้น ค่าป้อนและค่าขอบเขตแต่ละรายการอยู่ในตัวกรณีทดสอบของไฟล์ที่อ้างอิง | H3: ตรวจช่วงวันที่: ปฏิเสธวันที่ไม่มีจริงและช่วงที่วันสิ้นสุดอยู่ก่อนวันเริ่มต้น | I3: assertion ผ่านทั้งหมด | J3: Pass | K3: Pass | L3: ปานกลาง/P2 | N3: unit.log | O3: Claude (รันตาม TEST_PLAN) | P3: 46320
A4: UNIT-003 | B4: Unit/Integration (PGlite) | C4: การย้ายโครงสร้างฐานข้อมูลเก่า พิกัด และตัวกรองของผู้ดูแล ทำงานได้ในฐานทดสอบแยก | D4: การทดสอบหน่วยและระบบร่วม — test/audit-regression.test.cjs | E4: ใช้ฐานจำลอง PGlite แยกจากข้อมูลจริง พร้อมการย้ายโครงสร้างและเตรียมข้อมูลตามไฟล์ทดสอบ | F4: รันกรณีทดสอบอัตโนมัติที่อ้างอิง ตรวจเงื่อนไขยืนยันผล โดยไม่เปลี่ยนผลที่คาดหวัง | G4: ข้อมูลสังเคราะห์เท่านั้น ค่าป้อนและค่าขอบเขตแต่ละรายการอยู่ในตัวกรณีทดสอบของไฟล์ที่อ้างอิง | H4: การย้ายโครงสร้างฐานข้อมูลเก่า พิกัด และตัวกรองของผู้ดูแล ทำงานได้ในฐานทดสอบแยก | I4: assertion ผ่านทั้งหมด | J4: Pass | K4: Pass | L4: ปานกลาง/P2 | N4: unit.log | O4: Claude (รันตาม TEST_PLAN) | P4: 46320
A5: UNIT-004 | B5: Unit/Integration (PGlite) | C5: การเก็บกวาดไฟล์ประกาศลบเฉพาะไฟล์ของคำขอที่ล้มเหลว โดยคงไฟล์ของประกาศที่บันทึกสำเร็จและไฟล์เก่า | D5: การทดสอบหน่วยและระบบร่วม — test/audit-regression.test.cjs | E5: ใช้ฐานจำลอง PGlite แยกจากข้อมูลจริง พร้อมการย้ายโครงสร้างและเตรียมข้อมูลตามไฟล์ทดสอบ | F5: รันกรณีทดสอบอัตโนมัติที่อ้างอิง ตรวจเงื่อนไขยืนยันผล โดยไม่เปลี่ยนผลที่คาดหวัง | G5: ข้อมูลสังเคราะห์เท่านั้น ค่าป้อนและค่าขอบเขตแต่ละรายการอยู่ในตัวกรณีทดสอบของไฟล์ที่อ้างอิง | H5: การเก็บกวาดไฟล์ประกาศลบเฉพาะไฟล์ของคำขอที่ล้มเหลว โดยคงไฟล์ของประกาศที่บันทึกสำเร็จและไฟล์เก่า | I5: assertion ผ่านทั้งหมด | J5: Pass | K5: Pass | L5: ปานกลาง/P2 | N5: unit.log | O5: Claude (รันตาม TEST_PLAN) | P5: 46320
A6: UNIT-005 | B6: Unit/Integration (PGlite) | C6: แผนที่โหลดข้อมูลครบทุกหน้า คงสถานที่ที่ไม่รู้จัก และเคารพการปกปิดพิกัด | D6: การทดสอบหน่วยและระบบร่วม — test/audit-regression.test.cjs | E6: ใช้ฐานจำลอง PGlite แยกจากข้อมูลจริง พร้อมการย้ายโครงสร้างและเตรียมข้อมูลตามไฟล์ทดสอบ | F6: รันกรณีทดสอบอัตโนมัติที่อ้างอิง ตรวจเงื่อนไขยืนยันผล โดยไม่เปลี่ยนผลที่คาดหวัง | G6: ข้อมูลสังเคราะห์เท่านั้น ค่าป้อนและค่าขอบเขตแต่ละรายการอยู่ในตัวกรณีทดสอบของไฟล์ที่อ้างอิง | H6: แผนที่โหลดข้อมูลครบทุกหน้า คงสถานที่ที่ไม่รู้จัก และเคารพการปกปิดพิกัด | I6: assertion ผ่านทั้งหมด | J6: Pass | K6: Pass | L6: ปานกลาง/P2 | N6: unit.log | O6: Claude (รันตาม TEST_PLAN) | P6: 46320
A7: UNIT-006 | B7: Unit/Integration (PGlite) | C7: การตรวจ UI กับข้อมูลแบบอ่านอย่างเดียวตรวจพบค่าที่ไม่ตรงกันและฟิลด์ที่รั่วไหล พร้อมเปรียบเทียบวันที่ใน JSON ได้ถูกต้อง | D7: การทดสอบหน่วยและระบบร่วม — test/audit-ui-data.test.cjs | E7: ใช้ฐานจำลอง PGlite แยกจากข้อมูลจริง พร้อมการย้ายโครงสร้างและเตรียมข้อมูลตามไฟล์ทดสอบ | F7: รันกรณีทดสอบอัตโนมัติที่อ้างอิง ตรวจเงื่อนไขยืนยันผล โดยไม่เปลี่ยนผลที่คาดหวัง | G7: ข้อมูลสังเคราะห์เท่านั้น ค่าป้อนและค่าขอบเขตแต่ละรายการอยู่ในตัวกรณีทดสอบของไฟล์ที่อ้างอิง | H7: การตรวจ UI กับข้อมูลแบบอ่านอย่างเดียวตรวจพบค่าที่ไม่ตรงกันและฟิลด์ที่รั่วไหล พร้อมเปรียบเทียบวันที่ใน JSON ได้ถูกต้อง | I7: assertion ผ่านทั้งหมด | J7: Pass | K7: Pass | L7: ปานกลาง/P2 | N7: unit.log | O7: Claude (รันตาม TEST_PLAN) | P7: 46320
A8: UNIT-007 | B8: Unit/Integration (PGlite) | C8: Express ไม่เปิดเผยเวอร์ชันในส่วนหัวของการตอบกลับ | D8: การทดสอบหน่วยและระบบร่วม — test/backend.test.cjs | E8: ใช้ฐานจำลอง PGlite แยกจากข้อมูลจริง พร้อมการย้ายโครงสร้างและเตรียมข้อมูลตามไฟล์ทดสอบ | F8: รันกรณีทดสอบอัตโนมัติที่อ้างอิง ตรวจเงื่อนไขยืนยันผล โดยไม่เปลี่ยนผลที่คาดหวัง | G8: ข้อมูลสังเคราะห์เท่านั้น ค่าป้อนและค่าขอบเขตแต่ละรายการอยู่ในตัวกรณีทดสอบของไฟล์ที่อ้างอิง | H8: Express ไม่เปิดเผยเวอร์ชันในส่วนหัวของการตอบกลับ | I8: assertion ผ่านทั้งหมด | J8: Pass | K8: Pass | L8: ปานกลาง/P2 | N8: unit.log | O8: Claude (รันตาม TEST_PLAN) | P8: 46320
A9: UNIT-008 | B9: Unit/Integration (PGlite) | C9: หน้าเว็บสามารถแสดงรูปที่อัปโหลดจาก API คนละต้นทางได้ | D9: การทดสอบหน่วยและระบบร่วม — test/backend.test.cjs | E9: ใช้ฐานจำลอง PGlite แยกจากข้อมูลจริง พร้อมการย้ายโครงสร้างและเตรียมข้อมูลตามไฟล์ทดสอบ | F9: รันกรณีทดสอบอัตโนมัติที่อ้างอิง ตรวจเงื่อนไขยืนยันผล โดยไม่เปลี่ยนผลที่คาดหวัง | G9: ข้อมูลสังเคราะห์เท่านั้น ค่าป้อนและค่าขอบเขตแต่ละรายการอยู่ในตัวกรณีทดสอบของไฟล์ที่อ้างอิง | H9: หน้าเว็บสามารถแสดงรูปที่อัปโหลดจาก API คนละต้นทางได้ | I9: assertion ผ่านทั้งหมด | J9: Pass | K9: Pass | L9: ปานกลาง/P2 | N9: unit.log | O9: Claude (รันตาม TEST_PLAN) | P9: 46320
A10: UNIT-009 | B10: Unit/Integration (PGlite) | C10: ให้บริการรูป AVIF เดิมได้ แต่ยังปิดกั้นไฟล์ที่ไม่ใช่รูปภาพ | D10: การทดสอบหน่วยและระบบร่วม — test/backend.test.cjs | E10: ใช้ฐานจำลอง PGlite แยกจากข้อมูลจริง พร้อมการย้ายโครงสร้างและเตรียมข้อมูลตามไฟล์ทดสอบ | F10: รันกรณีทดสอบอัตโนมัติที่อ้างอิง ตรวจเงื่อนไขยืนยันผล โดยไม่เปลี่ยนผลที่คาดหวัง | G10: ข้อมูลสังเคราะห์เท่านั้น ค่าป้อนและค่าขอบเขตแต่ละรายการอยู่ในตัวกรณีทดสอบของไฟล์ที่อ้างอิง | H10: ให้บริการรูป AVIF เดิมได้ แต่ยังปิดกั้นไฟล์ที่ไม่ใช่รูปภาพ | I10: assertion ผ่านทั้งหมด | J10: Pass | K10: Pass | L10: ปานกลาง/P2 | N10: unit.log | O10: Claude (รันตาม TEST_PLAN) | P10: 46320
A11: UNIT-010 | B11: Unit/Integration (PGlite) | C11: CORS ยอมรับการติดต่อระหว่างเซิร์ฟเวอร์ ต้นทางที่อนุญาต และต้นทางพัฒนาในเครื่อง | D11: การทดสอบหน่วยและระบบร่วม — test/backend.test.cjs | E11: ใช้ฐานจำลอง PGlite แยกจากข้อมูลจริง พร้อมการย้ายโครงสร้างและเตรียมข้อมูลตามไฟล์ทดสอบ | F11: รันกรณีทดสอบอัตโนมัติที่อ้างอิง ตรวจเงื่อนไขยืนยันผล โดยไม่เปลี่ยนผลที่คาดหวัง | G11: ข้อมูลสังเคราะห์เท่านั้น ค่าป้อนและค่าขอบเขตแต่ละรายการอยู่ในตัวกรณีทดสอบของไฟล์ที่อ้างอิง | H11: CORS ยอมรับการติดต่อระหว่างเซิร์ฟเวอร์ ต้นทางที่อนุญาต และต้นทางพัฒนาในเครื่อง | I11: assertion ผ่านทั้งหมด | J11: Pass | K11: Pass | L11: ปานกลาง/P2 | N11: unit.log | O11: Claude (รันตาม TEST_PLAN) | P11: 46320
A12: UNIT-011 | B12: Unit/Integration (PGlite) | C12: CORS ปฏิเสธต้นทางผิดรูปแบบและต้นทางที่ไม่เชื่อถือ | D12: การทดสอบหน่วยและระบบร่วม — test/backend.test.cjs | E12: ใช้ฐานจำลอง PGlite แยกจากข้อมูลจริง พร้อมการย้ายโครงสร้างและเตรียมข้อมูลตามไฟล์ทดสอบ | F12: รันกรณีทดสอบอัตโนมัติที่อ้างอิง ตรวจเงื่อนไขยืนยันผล โดยไม่เปลี่ยนผลที่คาดหวัง | G12: ข้อมูลสังเคราะห์เท่านั้น ค่าป้อนและค่าขอบเขตแต่ละรายการอยู่ในตัวกรณีทดสอบของไฟล์ที่อ้างอิง | H12: CORS ปฏิเสธต้นทางผิดรูปแบบและต้นทางที่ไม่เชื่อถือ | I12: assertion ผ่านทั้งหมด | J12: Pass | K12: Pass | L12: ปานกลาง/P2 | N12: unit.log | O12: Claude (รันตาม TEST_PLAN) | P12: 46320
A13: UNIT-012 | B13: Unit/Integration (PGlite) | C13: ระบบส่งอีเมลต้องมีข้อมูลรับรองและบังคับใช้ TLS | D13: การทดสอบหน่วยและระบบร่วม — test/backend.test.cjs | E13: ใช้ฐานจำลอง PGlite แยกจากข้อมูลจริง พร้อมการย้ายโครงสร้างและเตรียมข้อมูลตามไฟล์ทดสอบ | F13: รันกรณีทดสอบอัตโนมัติที่อ้างอิง ตรวจเงื่อนไขยืนยันผล โดยไม่เปลี่ยนผลที่คาดหวัง | G13: ข้อมูลสังเคราะห์เท่านั้น ค่าป้อนและค่าขอบเขตแต่ละรายการอยู่ในตัวกรณีทดสอบของไฟล์ที่อ้างอิง | H13: ระบบส่งอีเมลต้องมีข้อมูลรับรองและบังคับใช้ TLS | I13: assertion ผ่านทั้งหมด | J13: Pass | K13: Pass | L13: ปานกลาง/P2 | N13: unit.log | O13: Claude (รันตาม TEST_PLAN) | P13: 46320
... A170: PG-035 | B170: PostgreSQL จริง (ฐานชั่วคราว) | C170: คำขอรับคืนจากประกาศของพบโดยตรงต้องตรวจตัวตนและยืนยันการส่งมอบ | D170: การทดสอบระบบร่วมบน PostgreSQL จริง — test/workflow.test.cjs | E170: ใช้ PostgreSQL 16 จริงที่สร้างใหม่แยกต่างหาก ใส่ข้อมูลสังเคราะห์และเตรียมโครงสร้างตามไฟล์ทดสอบ แล้วลบฐานทดสอบหลังจบ | F170: รันกรณีทดสอบอัตโนมัติที่อ้างอิง ตรวจเงื่อนไขยืนยันผล โดยไม่เปลี่ยนผลที่คาดหวัง | G170: ข้อมูลสังเคราะห์เท่านั้น ค่าป้อนและค่าขอบเขตแต่ละรายการอยู่ในตัวกรณีทดสอบของไฟล์ที่อ้างอิง | H170: คำขอรับคืนจากประกาศของพบโดยตรงต้องตรวจตัวตนและยืนยันการส่งมอบ | I170: รันบน PostgreSQL ฐานชั่วคราว (ลบแล้วหลังจบ): assertion ผ่านทั้งหมด | J170: Pass | K170: Pass | L170: ปานกลาง/P2 | N170: postgres.log, foundlost_test_*.json | O170: Claude (รันตาม TEST_PLAN) | P170: 46320
A171: PG-036 | B171: PostgreSQL จริง (ฐานชั่วคราว) | C171: หากตรวจยืนยันไม่ผ่านก่อนส่งมอบ ให้ปฏิเสธคู่เดิมและนำประกาศทั้งสองเข้าคิวค้นหาคู่ใหม่ | D171: การทดสอบระบบร่วมบน PostgreSQL จริง — test/workflow.test.cjs | E171: ใช้ PostgreSQL 16 จริงที่สร้างใหม่แยกต่างหาก ใส่ข้อมูลสังเคราะห์และเตรียมโครงสร้างตามไฟล์ทดสอบ แล้วลบฐานทดสอบหลังจบ | F171: รันกรณีทดสอบอัตโนมัติที่อ้างอิง ตรวจเงื่อนไขยืนยันผล โดยไม่เปลี่ยนผลที่คาดหวัง | G171: ข้อมูลสังเคราะห์เท่านั้น ค่าป้อนและค่าขอบเขตแต่ละรายการอยู่ในตัวกรณีทดสอบของไฟล์ที่อ้างอิง | H171: หากตรวจยืนยันไม่ผ่านก่อนส่งมอบ ให้ปฏิเสธคู่เดิมและนำประกาศทั้งสองเข้าคิวค้นหาคู่ใหม่ | I171: รันบน PostgreSQL ฐานชั่วคราว (ลบแล้วหลังจบ): assertion ผ่านทั้งหมด | J171: Pass | K171: Fail | L171: ปานกลาง/P2 | M171: QA-TEST-06 | N171: postgres.log, foundlost_test_*.json | O171: Claude (รันตาม TEST_PLAN) | P171: 46320
A172: PG-037 | B172: PostgreSQL จริง (ฐานชั่วคราว) | C172: ปฏิเสธคำขอรับคืนจากประกาศของพบโดยตรงก่อนส่งมอบได้ และสิ่งของกลับมาค้นหาได้อีก | D172: การทดสอบระบบร่วมบน PostgreSQL จริง — test/workflow.test.cjs | E172: ใช้ PostgreSQL 16 จริงที่สร้างใหม่แยกต่างหาก ใส่ข้อมูลสังเคราะห์และเตรียมโครงสร้างตามไฟล์ทดสอบ แล้วลบฐานทดสอบหลังจบ | F172: รันกรณีทดสอบอัตโนมัติที่อ้างอิง ตรวจเงื่อนไขยืนยันผล โดยไม่เปลี่ยนผลที่คาดหวัง | G172: ข้อมูลสังเคราะห์เท่านั้น ค่าป้อนและค่าขอบเขตแต่ละรายการอยู่ในตัวกรณีทดสอบของไฟล์ที่อ้างอิง | H172: ปฏิเสธคำขอรับคืนจากประกาศของพบโดยตรงก่อนส่งมอบได้ และสิ่งของกลับมาค้นหาได้อีก | I172: รันบน PostgreSQL ฐานชั่วคราว (ลบแล้วหลังจบ): assertion ผ่านทั้งหมด | J172: Pass | K172: Pass | L172: ปานกลาง/P2 | N172: postgres.log, foundlost_test_*.json | O172: Claude (รันตาม TEST_PLAN) | P172: 46320
A173: WEB-001 | B173: หน้าเว็บ (Playwright/Edge) | C173: หน้าหลักผ่านการตรวจ WCAG ระดับ AA อัตโนมัติบนคอมพิวเตอร์และมือถือ | D173: การใช้งานผ่านหน้าเว็บ — accessibility.spec.js | E173: ใช้ Edge Chromium, Vite พอร์ต 4173 และ Express พอร์ต 4181 ร่วมกับข้อมูล PGlite สังเคราะห์ ใช้ตัวรัน 1 ตัวและกำหนดเวลาเดิม โดย Google/SMTP จริงถูกแทนด้วยตัวทดสอบที่ระบุชัดเจน | F173: รันกรณีทดสอบอัตโนมัติที่อ้างอิง ตรวจเงื่อนไขยืนยันผล โดยไม่เปลี่ยนผลที่คาดหวัง | G173: ข้อมูลสังเคราะห์เท่านั้น ค่าป้อนและค่าขอบเขตแต่ละรายการอยู่ในตัวกรณีทดสอบของไฟล์ที่อ้างอิง | H173: หน้าหลักผ่านการตรวจ WCAG ระดับ AA อัตโนมัติบนคอมพิวเตอร์และมือถือ | I173: รันบน Microsoft Edge กับ API + ฐานจำลอง: ผ่านทั้งหมด | J173: Pass | K173: Pass | L173: ปานกลาง/P2 | N173: browser.log, browser-results.json | O173: Claude (รันตาม TEST_PLAN) | P173: 46320
A174: WEB-002 | B174: หน้าเว็บ (Playwright/Edge) | C174: หน้าเข้าใช้ผู้ดูแลแบบสาธารณะรองรับการเข้าถึงได้ แม้ยังไม่มีเซสชัน | D174: การใช้งานผ่านหน้าเว็บ — accessibility.spec.js | E174: ใช้ Edge Chromium, Vite พอร์ต 4173 และ Express พอร์ต 4181 ร่วมกับข้อมูล PGlite สังเคราะห์ ใช้ตัวรัน 1 ตัวและกำหนดเวลาเดิม โดย Google/SMTP จริงถูกแทนด้วยตัวทดสอบที่ระบุชัดเจน | F174: รันกรณีทดสอบอัตโนมัติที่อ้างอิง ตรวจเงื่อนไขยืนยันผล โดยไม่เปลี่ยนผลที่คาดหวัง | G174: ข้อมูลสังเคราะห์เท่านั้น ค่าป้อนและค่าขอบเขตแต่ละรายการอยู่ในตัวกรณีทดสอบของไฟล์ที่อ้างอิง | H174: หน้าเข้าใช้ผู้ดูแลแบบสาธารณะรองรับการเข้าถึงได้ แม้ยังไม่มีเซสชัน | I174: รันบน Microsoft Edge กับ API + ฐานจำลอง: ผ่านทั้งหมด | J174: Pass | K174: Pass | L174: ปานกลาง/P2 | N174: browser.log, browser-results.json | O174: Claude (รันตาม TEST_PLAN) | P174: 46320
A175: WEB-003 | B175: หน้าเว็บ (Playwright/Edge) | C175: ลิงก์ข้ามไปเนื้อหาและกล่องยืนยันออกจากระบบใช้งานด้วยแป้นพิมพ์และเทคโนโลยีช่วยการเข้าถึงได้ | D175: การใช้งานผ่านหน้าเว็บ — accessibility.spec.js | E175: ใช้ Edge Chromium, Vite พอร์ต 4173 และ Express พอร์ต 4181 ร่วมกับข้อมูล PGlite สังเคราะห์ ใช้ตัวรัน 1 ตัวและกำหนดเวลาเดิม โดย Google/SMTP จริงถูกแทนด้วยตัวทดสอบที่ระบุชัดเจน | F175: รันกรณีทดสอบอัตโนมัติที่อ้างอิง ตรวจเงื่อนไขยืนยันผล โดยไม่เปลี่ยนผลที่คาดหวัง | G175: ข้อมูลสังเคราะห์เท่านั้น ค่าป้อนและค่าขอบเขตแต่ละรายการอยู่ในตัวกรณีทดสอบของไฟล์ที่อ้างอิง | H175: ลิงก์ข้ามไปเนื้อหาและกล่องยืนยันออกจากระบบใช้งานด้วยแป้นพิมพ์และเทคโนโลยีช่วยการเข้าถึงได้ | I175: รันบน Microsoft Edge กับ API + ฐานจำลอง: ผ่านทั้งหมด | J175: Pass | K175: Pass | L175: ปานกลาง/P2 | N175: browser.log, browser-results.json | O175: Claude (รันตาม TEST_PLAN) | P175: 46320
A176: WEB-004 | B176: หน้าเว็บ (Playwright/Edge) | C176: ผู้ดูแลเข้าใช้และเปลี่ยนทุกหน้าในส่วนจัดการได้ด้วยข้อมูลจาก API ที่รันจริง | D176: การใช้งานผ่านหน้าเว็บ — admin.spec.js | E176: ใช้ Edge Chromium, Vite พอร์ต 4173 และ Express พอร์ต 4181 ร่วมกับข้อมูล PGlite สังเคราะห์ ใช้ตัวรัน 1 ตัวและกำหนดเวลาเดิม โดย Google/SMTP จริงถูกแทนด้วยตัวทดสอบที่ระบุชัดเจน | F176: รันกรณีทดสอบอัตโนมัติที่อ้างอิง ตรวจเงื่อนไขยืนยันผล โดยไม่เปลี่ยนผลที่คาดหวัง | G176: ข้อมูลสังเคราะห์เท่านั้น ค่าป้อนและค่าขอบเขตแต่ละรายการอยู่ในตัวกรณีทดสอบของไฟล์ที่อ้างอิง | H176: ผู้ดูแลเข้าใช้และเปลี่ยนทุกหน้าในส่วนจัดการได้ด้วยข้อมูลจาก API ที่รันจริง | I176: รันบน Microsoft Edge กับ API + ฐานจำลอง: ผ่านทั้งหมด | J176: Pass | K176: Pass | L176: ปานกลาง/P2 | N176: browser.log, browser-results.json | O176: Claude (รันตาม TEST_PLAN) | P176: 46320
A177: WEB-005 | B177: หน้าเว็บ (Playwright/Edge) | C177: ส่วนเจ้าหน้าที่มีหน้างานปฏิบัติการครบ 6 หน้า | D177: การใช้งานผ่านหน้าเว็บ — admin.spec.js | E177: ใช้ Edge Chromium, Vite พอร์ต 4173 และ Express พอร์ต 4181 ร่วมกับข้อมูล PGlite สังเคราะห์ ใช้ตัวรัน 1 ตัวและกำหนดเวลาเดิม โดย Google/SMTP จริงถูกแทนด้วยตัวทดสอบที่ระบุชัดเจน | F177: รันกรณีทดสอบอัตโนมัติที่อ้างอิง ตรวจเงื่อนไขยืนยันผล โดยไม่เปลี่ยนผลที่คาดหวัง | G177: ข้อมูลสังเคราะห์เท่านั้น ค่าป้อนและค่าขอบเขตแต่ละรายการอยู่ในตัวกรณีทดสอบของไฟล์ที่อ้างอิง | H177: ส่วนเจ้าหน้าที่มีหน้างานปฏิบัติการครบ 6 หน้า | I177: รันบน Microsoft Edge กับ API + ฐานจำลอง: ผ่านทั้งหมด | J177: Pass | K177: Pass | L177: ปานกลาง/P2 | N177: browser.log, browser-results.json | O177: Claude (รันตาม TEST_PLAN) | P177: 46320
A178: WEB-006 | B178: หน้าเว็บ (Playwright/Edge) | C178: หน้าจัดการพอดีกับคอมพิวเตอร์และมือถือ พร้อมบันทึกภาพหน้าจอจากข้อมูลที่รันจริง | D178: การใช้งานผ่านหน้าเว็บ — admin.spec.js | E178: ใช้ Edge Chromium, Vite พอร์ต 4173 และ Express พอร์ต 4181 ร่วมกับข้อมูล PGlite สังเคราะห์ ใช้ตัวรัน 1 ตัวและกำหนดเวลาเดิม โดย Google/SMTP จริงถูกแทนด้วยตัวทดสอบที่ระบุชัดเจน | F178: รันกรณีทดสอบอัตโนมัติที่อ้างอิง ตรวจเงื่อนไขยืนยันผล โดยไม่เปลี่ยนผลที่คาดหวัง | G178: ข้อมูลสังเคราะห์เท่านั้น ค่าป้อนและค่าขอบเขตแต่ละรายการอยู่ในตัวกรณีทดสอบของไฟล์ที่อ้างอิง | H178: หน้าจัดการพอดีกับคอมพิวเตอร์และมือถือ พร้อมบันทึกภาพหน้าจอจากข้อมูลที่รันจริง | I178: รันบน Microsoft Edge กับ API + ฐานจำลอง: ผ่านทั้งหมด | J178: Pass | K178: Pass | L178: ปานกลาง/P2 | N178: browser.log, browser-results.json | O178: Claude (รันตาม TEST_PLAN) | P178: 46320
A179: WEB-007 | B179: หน้าเว็บ (Playwright/Edge) | C179: หน้าต่างแก้ไขจุดรับฝากบันทึกได้ จำกัดโฟกัสภายในกล่อง และปิดด้วย Escape ได้ | D179: การใช้งานผ่านหน้าเว็บ — admin.spec.js | E179: ใช้ Edge Chromium, Vite พอร์ต 4173 และ Express พอร์ต 4181 ร่วมกับข้อมูล PGlite สังเคราะห์ ใช้ตัวรัน 1 ตัวและกำหนดเวลาเดิม โดย Google/SMTP จริงถูกแทนด้วยตัวทดสอบที่ระบุชัดเจน | F179: รันกรณีทดสอบอัตโนมัติที่อ้างอิง ตรวจเงื่อนไขยืนยันผล โดยไม่เปลี่ยนผลที่คาดหวัง | G179: ข้อมูลสังเคราะห์เท่านั้น ค่าป้อนและค่าขอบเขตแต่ละรายการอยู่ในตัวกรณีทดสอบของไฟล์ที่อ้างอิง | H179: หน้าต่างแก้ไขจุดรับฝากบันทึกได้ จำกัดโฟกัสภายในกล่อง และปิดด้วย Escape ได้ | I179: รันบน Microsoft Edge กับ API + ฐานจำลอง: ผ่านทั้งหมด | J179: Pass | K179: Pass | L179: ปานกลาง/P2 | N179: browser.log, browser-results.json | O179: Claude (รันตาม TEST_PLAN) | P179: 46320
A180: WEB-008 | B180: หน้าเว็บ (Playwright/Edge) | C180: หน้าสถิติดาวน์โหลดไฟล์ Excel จริง และมีรูปแบบรายงานสำหรับพิมพ์ | D180: การใช้งานผ่านหน้าเว็บ — admin.spec.js | E180: ใช้ Edge Chromium, Vite พอร์ต 4173 และ Express พอร์ต 4181 ร่วมกับข้อมูล PGlite สังเคราะห์ ใช้ตัวรัน 1 ตัวและกำหนดเวลาเดิม โดย Google/SMTP จริงถูกแทนด้วยตัวทดสอบที่ระบุชัดเจน | F180: รันกรณีทดสอบอัตโนมัติที่อ้างอิง ตรวจเงื่อนไขยืนยันผล โดยไม่เปลี่ยนผลที่คาดหวัง | G180: ข้อมูลสังเคราะห์เท่านั้น ค่าป้อนและค่าขอบเขตแต่ละรายการอยู่ในตัวกรณีทดสอบของไฟล์ที่อ้างอิง | H180: หน้าสถิติดาวน์โหลดไฟล์ Excel จริง และมีรูปแบบรายงานสำหรับพิมพ์ | I180: รันบน Microsoft Edge กับ API + ฐานจำลอง: ผ่านทั้งหมด | J180: Pass | K180: Pass | L180: ปานกลาง/P2 | N180: browser.log, browser-results.json | O180: Claude (รันตาม TEST_PLAN) | P180: 46320
A181: WEB-009 | B181: หน้าเว็บ (Playwright/Edge) | C181: ผู้ใช้ส่งคำขอโดยระบุลักษณะเฉพาะที่ปกปิด จากนั้นเจ้าหน้าที่อนุมัติและส่งมอบสิ่งของ | D181: การใช้งานผ่านหน้าเว็บ — admin.spec.js | E181: ใช้ Edge Chromium, Vite พอร์ต 4173 และ Express พอร์ต 4181 ร่วมกับข้อมูล PGlite สังเคราะห์ ใช้ตัวรัน 1 ตัวและกำหนดเวลาเดิม โดย Google/SMTP จริงถูกแทนด้วยตัวทดสอบที่ระบุชัดเจน | F181: รันกรณีทดสอบอัตโนมัติที่อ้างอิง ตรวจเงื่อนไขยืนยันผล โดยไม่เปลี่ยนผลที่คาดหวัง | G181: ข้อมูลสังเคราะห์เท่านั้น ค่าป้อนและค่าขอบเขตแต่ละรายการอยู่ในตัวกรณีทดสอบของไฟล์ที่อ้างอิง | H181: ผู้ใช้ส่งคำขอโดยระบุลักษณะเฉพาะที่ปกปิด จากนั้นเจ้าหน้าที่อนุมัติและส่งมอบสิ่งของ | I181: รันบน Microsoft Edge กับ API + ฐานจำลอง: ผ่านทั้งหมด | J181: Pass | K181: Pass | L181: ปานกลาง/P2 | N181: browser.log, browser-results.json | O181: Claude (รันตาม TEST_PLAN) | P181: 46320
A182: WEB-010 | B182: หน้าเว็บ (Playwright/Edge) | C182: เมื่อค้นหาล้มเหลว ให้ลบการ์ดผลเก่า และเมื่อลองใหม่ต้องแสดงผลใหม่ | D182: การใช้งานผ่านหน้าเว็บ — audit-regression.spec.js | E182: ใช้ Edge Chromium, Vite พอร์ต 4173 และ Express พอร์ต 4181 ร่วมกับข้อมูล PGlite สังเคราะห์ ใช้ตัวรัน 1 ตัวและกำหนดเวลาเดิม โดย Google/SMTP จริงถูกแทนด้วยตัวทดสอบที่ระบุชัดเจน | F182: รันกรณีทดสอบอัตโนมัติที่อ้างอิง ตรวจเงื่อนไขยืนยันผล โดยไม่เปลี่ยนผลที่คาดหวัง | G182: ข้อมูลสังเคราะห์เท่านั้น ค่าป้อนและค่าขอบเขตแต่ละรายการอยู่ในตัวกรณีทดสอบของไฟล์ที่อ้างอิง | H182: เมื่อค้นหาล้มเหลว ให้ลบการ์ดผลเก่า และเมื่อลองใหม่ต้องแสดงผลใหม่ | I182: รันบน Microsoft Edge กับ API + ฐานจำลอง: ผ่านทั้งหมด | J182: Pass | K182: Pass | L182: ปานกลาง/P2 | N182: browser.log, browser-results.json | O182: Claude (รันตาม TEST_PLAN) | P182: 46320
A183: WEB-011 | B183: หน้าเว็บ (Playwright/Edge) | C183: แผนที่โหลดข้อมูลตามเลขหน้า โดยไม่สร้างหมุดสมมติให้พิกัดที่ปกปิดหรือสถานที่กำหนดเอง | D183: การใช้งานผ่านหน้าเว็บ — audit-regression.spec.js | E183: ใช้ Edge Chromium, Vite พอร์ต 4173 และ Express พอร์ต 4181 ร่วมกับข้อมูล PGlite สังเคราะห์ ใช้ตัวรัน 1 ตัวและกำหนดเวลาเดิม โดย Google/SMTP จริงถูกแทนด้วยตัวทดสอบที่ระบุชัดเจน | F183: รันกรณีทดสอบอัตโนมัติที่อ้างอิง ตรวจเงื่อนไขยืนยันผล โดยไม่เปลี่ยนผลที่คาดหวัง | G183: ข้อมูลสังเคราะห์เท่านั้น ค่าป้อนและค่าขอบเขตแต่ละรายการอยู่ในตัวกรณีทดสอบของไฟล์ที่อ้างอิง | H183: แผนที่โหลดข้อมูลตามเลขหน้า โดยไม่สร้างหมุดสมมติให้พิกัดที่ปกปิดหรือสถานที่กำหนดเอง | I183: รันบน Microsoft Edge กับ API + ฐานจำลอง: ผ่านทั้งหมด | J183: Pass | K183: Pass | L183: ปานกลาง/P2 | N183: browser.log, browser-results.json | O183: Claude (รันตาม TEST_PLAN) | P183: 46320
... A192: WEB-020 | B192: หน้าเว็บ (Playwright/Edge) | C192: หน้าสาธารณะพอดีกับหน้าจอคอมพิวเตอร์และมือถือ | D192: การใช้งานผ่านหน้าเว็บ — design-responsive.spec.js | E192: ใช้ Edge Chromium, Vite พอร์ต 4173 และ Express พอร์ต 4181 ร่วมกับข้อมูล PGlite สังเคราะห์ ใช้ตัวรัน 1 ตัวและกำหนดเวลาเดิม โดย Google/SMTP จริงถูกแทนด้วยตัวทดสอบที่ระบุชัดเจน | F192: รันกรณีทดสอบอัตโนมัติที่อ้างอิง ตรวจเงื่อนไขยืนยันผล โดยไม่เปลี่ยนผลที่คาดหวัง | G192: ข้อมูลสังเคราะห์เท่านั้น ค่าป้อนและค่าขอบเขตแต่ละรายการอยู่ในตัวกรณีทดสอบของไฟล์ที่อ้างอิง | H192: หน้าสาธารณะพอดีกับหน้าจอคอมพิวเตอร์และมือถือ | I192: รันบน Microsoft Edge กับ API + ฐานจำลอง: ผ่านทั้งหมด | J192: Pass | K192: Pass | L192: ปานกลาง/P2 | N192: browser.log, browser-results.json | O192: Claude (รันตาม TEST_PLAN) | P192: 46320
A193: WEB-021 | B193: หน้าเว็บ (Playwright/Edge) | C193: กดการ์ดรายการแล้วเปิดหน้ารายละเอียดที่ใช้งานได้ | D193: การใช้งานผ่านหน้าเว็บ — design-responsive.spec.js | E193: ใช้ Edge Chromium, Vite พอร์ต 4173 และ Express พอร์ต 4181 ร่วมกับข้อมูล PGlite สังเคราะห์ ใช้ตัวรัน 1 ตัวและกำหนดเวลาเดิม โดย Google/SMTP จริงถูกแทนด้วยตัวทดสอบที่ระบุชัดเจน | F193: รันกรณีทดสอบอัตโนมัติที่อ้างอิง ตรวจเงื่อนไขยืนยันผล โดยไม่เปลี่ยนผลที่คาดหวัง | G193: ข้อมูลสังเคราะห์เท่านั้น ค่าป้อนและค่าขอบเขตแต่ละรายการอยู่ในตัวกรณีทดสอบของไฟล์ที่อ้างอิง | H193: กดการ์ดรายการแล้วเปิดหน้ารายละเอียดที่ใช้งานได้ | I193: รันบน Microsoft Edge กับ API + ฐานจำลอง: ผ่านทั้งหมด | J193: Pass | K193: Fail | L193: ปานกลาง/P2 | M193: QA-TEST-01 | N193: browser.log, browser-results.json | O193: Claude (รันตาม TEST_PLAN) | P193: 46320
A194: WEB-022 | B194: หน้าเว็บ (Playwright/Edge) | C194: โปรไฟล์และรายละเอียดสิ่งของแสดงค่าจาก API ถูกต้องบนคอมพิวเตอร์และมือถือ | D194: การใช้งานผ่านหน้าเว็บ — design-responsive.spec.js | E194: ใช้ Edge Chromium, Vite พอร์ต 4173 และ Express พอร์ต 4181 ร่วมกับข้อมูล PGlite สังเคราะห์ ใช้ตัวรัน 1 ตัวและกำหนดเวลาเดิม โดย Google/SMTP จริงถูกแทนด้วยตัวทดสอบที่ระบุชัดเจน | F194: รันกรณีทดสอบอัตโนมัติที่อ้างอิง ตรวจเงื่อนไขยืนยันผล โดยไม่เปลี่ยนผลที่คาดหวัง | G194: ข้อมูลสังเคราะห์เท่านั้น ค่าป้อนและค่าขอบเขตแต่ละรายการอยู่ในตัวกรณีทดสอบของไฟล์ที่อ้างอิง | H194: โปรไฟล์และรายละเอียดสิ่งของแสดงค่าจาก API ถูกต้องบนคอมพิวเตอร์และมือถือ | I194: รันบน Microsoft Edge กับ API + ฐานจำลอง: ผ่านทั้งหมด | J194: Pass | K194: Fail | L194: ปานกลาง/P2 | M194: QA-TEST-01 | N194: browser.log, browser-results.json | O194: Claude (รันตาม TEST_PLAN) | P194: 46320
A195: WEB-023 | B195: หน้าเว็บ (Playwright/Edge) | C195: ฟอร์มแจ้งของพบให้เลือกเฉพาะจุดรับฝากที่ระบบตั้งค่าไว้ | D195: การใช้งานผ่านหน้าเว็บ — design-responsive.spec.js | E195: ใช้ Edge Chromium, Vite พอร์ต 4173 และ Express พอร์ต 4181 ร่วมกับข้อมูล PGlite สังเคราะห์ ใช้ตัวรัน 1 ตัวและกำหนดเวลาเดิม โดย Google/SMTP จริงถูกแทนด้วยตัวทดสอบที่ระบุชัดเจน | F195: รันกรณีทดสอบอัตโนมัติที่อ้างอิง ตรวจเงื่อนไขยืนยันผล โดยไม่เปลี่ยนผลที่คาดหวัง | G195: ข้อมูลสังเคราะห์เท่านั้น ค่าป้อนและค่าขอบเขตแต่ละรายการอยู่ในตัวกรณีทดสอบของไฟล์ที่อ้างอิง | H195: ฟอร์มแจ้งของพบให้เลือกเฉพาะจุดรับฝากที่ระบบตั้งค่าไว้ | I195: รันบน Microsoft Edge กับ API + ฐานจำลอง: ผ่านทั้งหมด | J195: Pass | K195: Pass | L195: ปานกลาง/P2 | N195: browser.log, browser-results.json | O195: Claude (รันตาม TEST_PLAN) | P195: 46320
A196: WEB-024 | B196: หน้าเว็บ (Playwright/Edge) | C196: แบบอักษร Prompt โหลดและถูกใช้ในหน้าสาธารณะ หน้าเข้าใช้ หน้าผู้ดูแล และหน้าแอป | D196: การใช้งานผ่านหน้าเว็บ — font.spec.js | E196: ใช้ Edge Chromium, Vite พอร์ต 4173 และ Express พอร์ต 4181 ร่วมกับข้อมูล PGlite สังเคราะห์ ใช้ตัวรัน 1 ตัวและกำหนดเวลาเดิม โดย Google/SMTP จริงถูกแทนด้วยตัวทดสอบที่ระบุชัดเจน | F196: รันกรณีทดสอบอัตโนมัติที่อ้างอิง ตรวจเงื่อนไขยืนยันผล โดยไม่เปลี่ยนผลที่คาดหวัง | G196: ข้อมูลสังเคราะห์เท่านั้น ค่าป้อนและค่าขอบเขตแต่ละรายการอยู่ในตัวกรณีทดสอบของไฟล์ที่อ้างอิง | H196: แบบอักษร Prompt โหลดและถูกใช้ในหน้าสาธารณะ หน้าเข้าใช้ หน้าผู้ดูแล และหน้าแอป | I196: รันบน Microsoft Edge กับ API + ฐานจำลอง: ผ่านทั้งหมด | J196: Pass | K196: Pass | L196: ปานกลาง/P2 | N196: browser.log, browser-results.json | O196: Claude (รันตาม TEST_PLAN) | P196: 46320
A197: WEB-025 | B197: หน้าเว็บ (Playwright/Edge) | C197: หน้าเข้าใช้มีข้อความเตือนใต้ช่องตามภาษาที่เลือก โฟกัสช่องผิด และไม่เปลี่ยนไบต์รหัสผ่าน | D197: การใช้งานผ่านหน้าเว็บ — form-validation.spec.js | E197: ใช้ Edge Chromium, Vite พอร์ต 4173 และ Express พอร์ต 4181 ร่วมกับข้อมูล PGlite สังเคราะห์ ใช้ตัวรัน 1 ตัวและกำหนดเวลาเดิม โดย Google/SMTP จริงถูกแทนด้วยตัวทดสอบที่ระบุชัดเจน | F197: รันกรณีทดสอบอัตโนมัติที่อ้างอิง ตรวจเงื่อนไขยืนยันผล โดยไม่เปลี่ยนผลที่คาดหวัง | G197: ข้อมูลสังเคราะห์เท่านั้น ค่าป้อนและค่าขอบเขตแต่ละรายการอยู่ในตัวกรณีทดสอบของไฟล์ที่อ้างอิง | H197: หน้าเข้าใช้มีข้อความเตือนใต้ช่องตามภาษาที่เลือก โฟกัสช่องผิด และไม่เปลี่ยนไบต์รหัสผ่าน | I197: รันบน Microsoft Edge กับ API + ฐานจำลอง: ผ่านทั้งหมด | J197: Pass | K197: Pass | L197: ปานกลาง/P2 | N197: browser.log, browser-results.json | O197: Claude (รันตาม TEST_PLAN) | P197: 46320
A198: WEB-026 | B198: หน้าเว็บ (Playwright/Edge) | C198: ช่องตัวเลขที่ลบว่างต้องยังว่าง และส่งค่า 0 ที่กรอกจริงเป็นตัวเลข | D198: การใช้งานผ่านหน้าเว็บ — form-validation.spec.js | E198: ใช้ Edge Chromium, Vite พอร์ต 4173 และ Express พอร์ต 4181 ร่วมกับข้อมูล PGlite สังเคราะห์ ใช้ตัวรัน 1 ตัวและกำหนดเวลาเดิม โดย Google/SMTP จริงถูกแทนด้วยตัวทดสอบที่ระบุชัดเจน | F198: รันกรณีทดสอบอัตโนมัติที่อ้างอิง ตรวจเงื่อนไขยืนยันผล โดยไม่เปลี่ยนผลที่คาดหวัง | G198: ข้อมูลสังเคราะห์เท่านั้น ค่าป้อนและค่าขอบเขตแต่ละรายการอยู่ในตัวกรณีทดสอบของไฟล์ที่อ้างอิง | H198: ช่องตัวเลขที่ลบว่างต้องยังว่าง และส่งค่า 0 ที่กรอกจริงเป็นตัวเลข | I198: รันบน Microsoft Edge กับ API + ฐานจำลอง: ผ่านทั้งหมด | J198: Pass | K198: Pass | L198: ปานกลาง/P2 | N198: browser.log, browser-results.json | O198: Claude (รันตาม TEST_PLAN) | P198: 46320
A199: WEB-027 | B199: หน้าเว็บ (Playwright/Edge) | C199: คำขอที่มีแต่ช่องว่างถูกปิดกั้นก่อนเรียก API ที่ /services | D199: การใช้งานผ่านหน้าเว็บ — form-validation.spec.js | E199: ใช้ Edge Chromium, Vite พอร์ต 4173 และ Express พอร์ต 4181 ร่วมกับข้อมูล PGlite สังเคราะห์ ใช้ตัวรัน 1 ตัวและกำหนดเวลาเดิม โดย Google/SMTP จริงถูกแทนด้วยตัวทดสอบที่ระบุชัดเจน | F199: รันกรณีทดสอบอัตโนมัติที่อ้างอิง ตรวจเงื่อนไขยืนยันผล โดยไม่เปลี่ยนผลที่คาดหวัง | G199: ข้อมูลสังเคราะห์เท่านั้น ค่าป้อนและค่าขอบเขตแต่ละรายการอยู่ในตัวกรณีทดสอบของไฟล์ที่อ้างอิง | H199: คำขอที่มีแต่ช่องว่างถูกปิดกั้นก่อนเรียก API ที่ /services | I199: รันบน Microsoft Edge กับ API + ฐานจำลอง: ผ่านทั้งหมด | J199: Pass | K199: Pass | L199: ปานกลาง/P2 | N199: browser.log, browser-results.json | O199: Claude (รันตาม TEST_PLAN) | P199: 46320
A200: WEB-028 | B200: หน้าเว็บ (Playwright/Edge) | C200: คำขอที่มีแต่ช่องว่างถูกปิดกั้นก่อนเรียก API ที่ /privacy | D200: การใช้งานผ่านหน้าเว็บ — form-validation.spec.js | E200: ใช้ Edge Chromium, Vite พอร์ต 4173 และ Express พอร์ต 4181 ร่วมกับข้อมูล PGlite สังเคราะห์ ใช้ตัวรัน 1 ตัวและกำหนดเวลาเดิม โดย Google/SMTP จริงถูกแทนด้วยตัวทดสอบที่ระบุชัดเจน | F200: รันกรณีทดสอบอัตโนมัติที่อ้างอิง ตรวจเงื่อนไขยืนยันผล โดยไม่เปลี่ยนผลที่คาดหวัง | G200: ข้อมูลสังเคราะห์เท่านั้น ค่าป้อนและค่าขอบเขตแต่ละรายการอยู่ในตัวกรณีทดสอบของไฟล์ที่อ้างอิง | H200: คำขอที่มีแต่ช่องว่างถูกปิดกั้นก่อนเรียก API ที่ /privacy | I200: รันบน Microsoft Edge กับ API + ฐานจำลอง: ผ่านทั้งหมด | J200: Pass | K200: Pass | L200: ปานกลาง/P2 | N200: browser.log, browser-results.json | O200: Claude (รันตาม TEST_PLAN) | P200: 46320
A201: WEB-029 | B201: หน้าเว็บ (Playwright/Edge) | C201: หน้า OTP อธิบายเหตุผลที่ปุ่มถูกปิด และอัปเดตจำนวนหลักที่กรอกในทั้งสองภาษา | D201: การใช้งานผ่านหน้าเว็บ — form-validation.spec.js | E201: ใช้ Edge Chromium, Vite พอร์ต 4173 และ Express พอร์ต 4181 ร่วมกับข้อมูล PGlite สังเคราะห์ ใช้ตัวรัน 1 ตัวและกำหนดเวลาเดิม โดย Google/SMTP จริงถูกแทนด้วยตัวทดสอบที่ระบุชัดเจน | F201: รันกรณีทดสอบอัตโนมัติที่อ้างอิง ตรวจเงื่อนไขยืนยันผล โดยไม่เปลี่ยนผลที่คาดหวัง | G201: ข้อมูลสังเคราะห์เท่านั้น ค่าป้อนและค่าขอบเขตแต่ละรายการอยู่ในตัวกรณีทดสอบของไฟล์ที่อ้างอิง | H201: หน้า OTP อธิบายเหตุผลที่ปุ่มถูกปิด และอัปเดตจำนวนหลักที่กรอกในทั้งสองภาษา | I201: รันบน Microsoft Edge กับ API + ฐานจำลอง: ผ่านทั้งหมด | J201: Pass | K201: Pass | L201: ปานกลาง/P2 | N201: browser.log, browser-results.json | O201: Claude (รันตาม TEST_PLAN) | P201: 46320
A202: WEB-030 | B202: หน้าเว็บ (Playwright/Edge) | C202: รูปที่ลากวางผ่านการตรวจอัปโหลด และการล้างฟอร์มลบข้อความผิดพลาดเดิม | D202: การใช้งานผ่านหน้าเว็บ — form-validation.spec.js | E202: ใช้ Edge Chromium, Vite พอร์ต 4173 และ Express พอร์ต 4181 ร่วมกับข้อมูล PGlite สังเคราะห์ ใช้ตัวรัน 1 ตัวและกำหนดเวลาเดิม โดย Google/SMTP จริงถูกแทนด้วยตัวทดสอบที่ระบุชัดเจน | F202: รันกรณีทดสอบอัตโนมัติที่อ้างอิง ตรวจเงื่อนไขยืนยันผล โดยไม่เปลี่ยนผลที่คาดหวัง | G202: ข้อมูลสังเคราะห์เท่านั้น ค่าป้อนและค่าขอบเขตแต่ละรายการอยู่ในตัวกรณีทดสอบของไฟล์ที่อ้างอิง | H202: รูปที่ลากวางผ่านการตรวจอัปโหลด และการล้างฟอร์มลบข้อความผิดพลาดเดิม | I202: รันบน Microsoft Edge กับ API + ฐานจำลอง: ผ่านทั้งหมด | J202: Pass | K202: Pass | L202: ปานกลาง/P2 | N202: browser.log, browser-results.json | O202: Claude (รันตาม TEST_PLAN) | P202: 46320
A203: WEB-031 | B203: หน้าเว็บ (Playwright/Edge) | C203: หน้าตรวจคำขอรับคืนโดยตรงของเจ้าหน้าที่อธิบายเมื่อขาดหมายเหตุหรือการยืนยันตัวตน | D203: การใช้งานผ่านหน้าเว็บ — form-validation.spec.js | E203: ใช้ Edge Chromium, Vite พอร์ต 4173 และ Express พอร์ต 4181 ร่วมกับข้อมูล PGlite สังเคราะห์ ใช้ตัวรัน 1 ตัวและกำหนดเวลาเดิม โดย Google/SMTP จริงถูกแทนด้วยตัวทดสอบที่ระบุชัดเจน | F203: รันกรณีทดสอบอัตโนมัติที่อ้างอิง ตรวจเงื่อนไขยืนยันผล โดยไม่เปลี่ยนผลที่คาดหวัง | G203: ข้อมูลสังเคราะห์เท่านั้น ค่าป้อนและค่าขอบเขตแต่ละรายการอยู่ในตัวกรณีทดสอบของไฟล์ที่อ้างอิง | H203: หน้าตรวจคำขอรับคืนโดยตรงของเจ้าหน้าที่อธิบายเมื่อขาดหมายเหตุหรือการยืนยันตัวตน | I203: รันบน Microsoft Edge กับ API + ฐานจำลอง: ผ่านทั้งหมด | J203: Pass | K203: Pass | L203: ปานกลาง/P2 | N203: browser.log, browser-results.json | O203: Claude (รันตาม TEST_PLAN) | P203: 46320
A204: WEB-032 | B204: หน้าเว็บ (Playwright/Edge) | C204: เจ้าหน้าที่ปฏิเสธคำขอที่อนุมัติแล้วก่อนส่งมอบได้ โดยต้องระบุเหตุผล | D204: การใช้งานผ่านหน้าเว็บ — form-validation.spec.js | E204: ใช้ Edge Chromium, Vite พอร์ต 4173 และ Express พอร์ต 4181 ร่วมกับข้อมูล PGlite สังเคราะห์ ใช้ตัวรัน 1 ตัวและกำหนดเวลาเดิม โดย Google/SMTP จริงถูกแทนด้วยตัวทดสอบที่ระบุชัดเจน | F204: รันกรณีทดสอบอัตโนมัติที่อ้างอิง ตรวจเงื่อนไขยืนยันผล โดยไม่เปลี่ยนผลที่คาดหวัง | G204: ข้อมูลสังเคราะห์เท่านั้น ค่าป้อนและค่าขอบเขตแต่ละรายการอยู่ในตัวกรณีทดสอบของไฟล์ที่อ้างอิง | H204: เจ้าหน้าที่ปฏิเสธคำขอที่อนุมัติแล้วก่อนส่งมอบได้ โดยต้องระบุเหตุผล | I204: รันบน Microsoft Edge กับ API + ฐานจำลอง: ผ่านทั้งหมด | J204: Pass | K204: Pass | L204: ปานกลาง/P2 | N204: browser.log, browser-results.json | O204: Claude (รันตาม TEST_PLAN) | P204: 46320
...

Sheet User Manual
A1: รหัส | B1: หัวข้อในคู่มือ | C1: เรื่อง | D1: ขั้นตอนที่ทำ | E1: สิ่งที่คู่มือบอก (ผลที่คาดหวัง) | F1: ผลจริงบนหน้าจอ | G1: สถานะ | H1: คู่มือตรงกับระบบ? | I1: ภาพหลักฐาน (output/manual-test-evidence/user-manual) | J1: ผู้ทดสอบ | K1: วันที่
A2: UM-01 | B2: ข้อ 1 | C2: หน้าเริ่มต้นและหน้า login | D2: เปิด /login | E2: ไม่มี navbar บนหน้าเริ่มต้นและ login มีตัวเลือก “เข้าใช้ครั้งแรก / ยังไม่มีรหัสผ่าน” | F2: /login ไม่มี navbar (มีแค่ปุ่ม “ลงชื่อเข้าใช้” และ “เข้าสู่ระบบ”) /signin ไม่มี navbar เช่นกัน ปุ่มเข้าใช้ครั้งแรกบนหน้าจอชื่อ “ลงชื่อเข้าใช้” ไม่ใช่ “เข้าใช้ครั้งแรก / ยังไม่มีรหัสผ่าน” | G2: Pass | H2: ไม่ตรง: ชื่อปุ่มในคู่มือต่างจากหน้าจอ | I2: UM-01-login.png, UM-01-signin.png | J2: Claude (รันตาม TEST_PLAN) | K2: 46320
A3: UM-02 | B3: ข้อ 1–2 | C3: เข้าใช้ครั้งแรกด้วย OTP และตั้งรหัสผ่าน | D3: กด ลงชื่อเข้าใช้ → กรอกอีเมล @ku.th → ส่ง OTP → กรอก OTP → ตั้งรหัสผ่าน → รับทราบประกาศ | E3: ยืนยัน OTP แล้วตั้งรหัสผ่าน 15–128 ตัว กรอกรหัสนิสิต/ผู้ใช้ ชื่อ นามสกุล และอ่านประกาศความเป็นส่วนตัวก่อนรับทราบ | F3: OTP ส่งและยืนยันได้ หน้าตั้งรหัสผ่านมีเฉพาะ รหัสผ่าน / ยืนยันรหัสผ่าน / รับทราบประกาศ (มีลิงก์ประกาศ) ไม่มีช่องรหัสนิสิต ชื่อ นามสกุล ระบบใช้ข้อมูลจากทะเบียนแทน (ตาม README) บันทึกแล้วเข้า /foundPage | G3: Pass | H3: ไม่ตรง: คู่มือบอกให้กรอกรหัสนิสิต ชื่อ นามสกุล แต่หน้าจอไม่มีช่องเหล่านี้ (ตั้งใจออกแบบให้ใช้ข้อมูลทะเบียน) | I3: UM-02-create-password.png | J3: Claude (รันตาม TEST_PLAN) | K3: 46320
A4: UM-03 | B4: ข้อ 2 | C4: เข้าใช้ครั้งต่อไปและลืมรหัสผ่าน | D4: ออกจากระบบ → /signin → กรอกอีเมลและรหัสผ่าน | E4: เข้าใช้ด้วยอีเมลและรหัสผ่าน ถ้าลืมใช้ “ลืมรหัสผ่าน” | F4: เข้าสู่ระบบด้วยอีเมล + รหัสผ่านสำเร็จ ไปที่ /foundPage มีลิงก์ “ลืมรหัสผ่าน” (flow ลืมรหัสผ่านผ่านใน WEB otp-flow) | G4: Pass | H4: ตรง | I4: - | J4: Claude (รันตาม TEST_PLAN) | K4: 46320
A5: UM-04 | B5: ข้อ 3 | C5: แจ้งของหาย/แจ้งพบ | D5: เปิด /lostItem และ /foundItem ตรวจช่องข้อมูล | E5: ระบุประเภท วันที่ สถานที่ รายละเอียด (ยี่ห้อ รุ่น ตำหนิ) แนบ JPG/PNG/WebP เลือกสีจากสีแนะนำหรือตารางสี แยกลักษณะเฉพาะไว้ช่องข้อมูลยืนยัน | F5: ฟอร์มมี รูป (accept JPG/PNG/WebP ≤5 MB), สีสิ่งของ + “เลือกจากตารางสี”, วันที่, ชื่อ, หมวดหมู่, สถานที่ + แผนที่, รายละเอียดเพิ่มเติม, ช่อง “ตำหนิ/ลักษณะเฉพาะ (เห็นเฉพาะเจ้าหน้าที่)” แยกต่างหาก ฟอร์มแจ้งพบมีเลือกจุดรับฝาก ไม่มีช่องยี่ห้อ/รุ่น/เวลาแยก (ใส่ในรายละเอียดได้) | G5: Pass | H5: ตรงบางส่วน: ส่วนภาษาอังกฤษพูดถึง date/time และ brand/model เหมือนเป็นช่องแยก แต่ฟอร์มไม่มีช่องเวลา ยี่ห้อ รุ่น | I5: UM-04-lostItem.png, UM-04-foundItem.png | J5: Claude (รันตาม TEST_PLAN) | K5: 46320
A6: UM-05 | B6: ข้อ 3 | C6: หลังส่งมอบคืนแล้ว | D6: เจ้าของยื่นคำขอ → เจ้าหน้าที่อนุมัติ → ยืนยันส่งมอบ → ตรวจหน้ารายการ ประวัติ และประวัติการคืนของเจ้าหน้าที่ | E6: รายการของหายและของพบหายจากหน้ารายการโพสต์ เจ้าของยังดูได้ในประวัติ เจ้าหน้าที่ยังตรวจประวัติการคืนได้ | F6: หลังส่งมอบ: ไม่แสดงในหน้ารายการของหาย/ของพบ, หน้าประวัติของเจ้าของแสดง “สถานะ: คืนแล้ว”, หน้า /staff/returns-history ของเจ้าหน้าที่แสดงรายการ | G6: Pass | H6: ตรง | I6: UM-05-tracking-*.png, UM-05-history.png, UM-05-staff-returns-history.png | J6: Claude (รันตาม TEST_PLAN) | K6: 46320
A7: UM-06 | B7: ข้อ 4 | C7: หน้ารายการ ค้นหา กรอง เปลี่ยนหน้า | D7: เปิด /lostPage และ /foundPage กดตัวกรอง ก่อนหน้า/ถัดไป เปิดรายละเอียด | E7: กด “รายการของหาย” / “รายการของพบ” เพื่อเปลี่ยนหน้า กรองและค้นหาแล้วใช้ปุ่มก่อนหน้า/ถัดไป หากเห็น “รายละเอียดถูกปกปิด” เป็นการป้องกันการแอบอ้าง | F7: มีตัวกรองด่วน (ทั้งหมด กระเป๋า กุญแจ …) ปุ่ม ‹ ก่อนหน้า / ถัดไป › และตัวบอกหน้า ลิงก์เปลี่ยนหน้าชื่อ “รายการของที่พบล่าสุด / รายการของที่หายล่าสุด” หน้ารายละเอียดแสดง “ปกปิดข้อมูลผู้แจ้ง” ไม่ใช่ “รายละเอียดถูกปกปิด” | G7: Pass | H7: ไม่ตรง: ชื่อปุ่มเปลี่ยนหน้าและข้อความปกปิดต่างจากคู่มือ | I7: UM-06-*.png | J7: Claude (รันตาม TEST_PLAN) | K7: 46320
A8: UM-07 | B8: ข้อ 5 | C8: หน้าแจ้งเตือน | D8: เปิด /notifications | E8: แสดงคู่ที่อาจตรงกันและการแจ้งเตือนจากระบบ เปิดรายการจากปุ่มข้างรีเฟรช คะแนนเป็นเพียงความคล้าย | F8: แสดง “พบคู่สิ่งของใหม่” พร้อมปุ่ม “ดูคู่ที่ตรงกัน” มีปุ่ม “รีเฟรชผลจับคู่” “อ่านทั้งหมด” “อ่านแล้ว” | G8: Pass | H8: ตรง | I8: UM-07-notifications.png | J8: Claude (รันตาม TEST_PLAN) | K8: 46320
A9: UM-08 | B9: ข้อ 5 | C9: Claim โดยไม่ลงประกาศของหาย + ติดตาม | D9: ผู้ใช้ใหม่ (ไม่มีประกาศของหาย) เปิดของพบ → กดยืนยันความเป็นเจ้าของ → กรอกลักษณะเฉพาะ → ส่ง → เปิด “จุดรับฝากและการติดตาม” | E9: กด Claim ได้แม้ยังไม่ลงประกาศของหาย ระบุลักษณะเฉพาะ รอเจ้าหน้าที่ตรวจ หน้าติดตามแสดงวันเวลาที่ยื่นและสถานะ | F9: ฟอร์มแจ้ง “ยังไม่ได้ลงประกาศของหายก็ส่งคำขอได้” ส่งสำเร็จ “ส่งคำขอแล้ว เจ้าหน้าที่จะตรวจสอบหลักฐาน…” หน้าติดตามแสดง “คำขอ #1 — รอตรวจสอบ · คำขอโดยไม่ลงประกาศของหาย · ยื่นคำขอเมื่อ 25 ต.ค. 2569 17:42” และจุดรับคืน/เวลาเปิด ปุ่มบนหน้าจอชื่อ “ยืนยันความเป็นเจ้าของ” | G9: Pass | H9: ตรงบางส่วน: ส่วนภาษาไทยเรียกปุ่มว่า “Claim” แต่หน้าจอใช้ “ยืนยันความเป็นเจ้าของ” | I9: UM-08-direct-claim.png, UM-08-tracking-pending.png | J9: Claude (รันตาม TEST_PLAN) | K9: 46320
A10: UM-09 | B10: ข้อ 5 | C10: สถานะ “ยืนยันเจ้าของแล้ว · รอส่งมอบ” และ “คืนแล้ว” | D10: เจ้าหน้าที่อนุมัติ แล้วยืนยันส่งมอบ ตรวจหน้าติดตามของเจ้าของ | E10: หลังอนุมัติ: “ยืนยันเจ้าของแล้ว · รอส่งมอบ” (ยังไม่ใช่คืนแล้ว) หลังส่งมอบจริง: “คืนแล้ว” | F10: หลังอนุมัติ: “คำขอ #2 — ยืนยันเจ้าของแล้ว · รอส่งมอบ” หลังส่งมอบ: “คำขอ #2 — รับคืนแล้ว · ส่งมอบคืนเมื่อ …” (หน้าประวัติแสดง “คืนแล้ว”) | G10: Pass | H10: ตรงบางส่วน: หน้าติดตามใช้คำ “รับคืนแล้ว” ส่วนคู่มือใช้ “คืนแล้ว” | I10: UM-05-tracking-approved.png, UM-05-tracking-returned.png | J10: Claude (รันตาม TEST_PLAN) | K10: 46320
A11: UM-10 | B11: ข้อ 6 | C11: เมนูโปรไฟล์ | D11: เปิด /profile | E11: มี รายการของฉัน การติดตาม ความเป็นส่วนตัว และออกจากระบบ ไม่ซ้ำใน navbar | F11: หน้าโปรไฟล์มีครบ 4 เมนู navbar ด้านบนไม่มีเมนูเหล่านี้ซ้ำ | G11: Pass | H11: ตรง | I11: UM-09-profile.png | J11: Claude (รันตาม TEST_PLAN) | K11: 46320
A12: UM-11 | B12: ข้อ 6–7 | C12: รูปโปรไฟล์ | D12: เลือกรูป → บันทึกโปรไฟล์ → โหลดหน้าใหม่ | E12: รูปบันทึกไฟล์ใน backend/assets/profileUploads และเส้นทางใน users.profile_image แก้/ลบผ่านปุ่มในโปรไฟล์ | F12: profile_image = /assets/profileUploads/<uuid>.png แสดงรูปหลังโหลดหน้าใหม่ มีปุ่มลบรูป | G12: Pass | H12: ตรง | I12: UM-10-profile-photo.png | J12: Claude (รันตาม TEST_PLAN) | K12: 46320
A13: UM-12 | B13: ข้อ 7 | C13: ข้อมูลตัวตนแก้เองไม่ได้ / ขอแก้ไขผ่าน Privacy | D13: ตรวจช่องชื่อ อีเมล รหัส → ไป Privacy เลือก “ขอแก้ไข” → ส่ง | E13: ชื่อ/นามสกุล อีเมล รหัสผู้ใช้ไม่ให้แก้เอง ยื่น “ขอแก้ไข” ในหน้า Privacy ให้แอดมินตรวจ | F13: ช่องชื่อ นามสกุล รหัส อีเมล เป็น disabled ส่งคำขอแก้ไขแล้วแสดง “บันทึกคำขอแล้ว ผู้ดูแลต้องตรวจสอบและตอบกลับ · #1 correction: pending” | G13: Pass | H13: ตรง | I13: UM-11-privacy-request.png | J13: Claude (รันตาม TEST_PLAN) | K13: 46320
... A20: UM-19 | B20: Troubleshooting | C20: OTP: 503 เมื่อบริการอีเมลยังไม่พร้อม | D20: - | E20: 503 หมายถึงบริการอีเมลยังไม่พร้อม | F20: ไม่ได้จำลองการปิดบริการอีเมลในรอบเดินตามคู่มือ (ชุด unit มีเฉพาะ Google login ตอบ 503 เมื่อปิด ไม่ใช่ OTP) | G20: Not Run | H20: ยังไม่ได้ตรวจ | I20: - | J20: Claude (รันตาม TEST_PLAN) | K20: 46320

Sheet ขั้นตอนตาม Test Plan
A1: ขั้นที่ | B1: สิ่งที่ TEST_PLAN กำหนด | C1: สิ่งที่ทำและผล | D1: สถานะ
A2: 1 | B2: วิเคราะห์ routes, controllers, schema, env, startup, สถานะ Git โดยไม่แสดง secrets | C2: อ่าน routes/controllers/validation/schema; ตรวจเฉพาะการมีอยู่ของค่า env (ไม่แสดงค่า); Git branch docs/manual-test-cases มีไฟล์ที่ยังไม่ commit เดิมของผู้ใช้และงานรอบก่อน | D2: ทำแล้ว
A3: 2 | B3: รัน Node unit/integration ทุกไฟล์ test/*.test.cjs บน PGlite แยก | C3: 304 tests: ผ่าน 298, ไม่ผ่าน 0, ข้าม 2 (symlink บน Windows, smoke โมเดล DINOv2 แบบเลือกเปิด), TODO 4 (บั๊กที่บันทึกไว้) | D3: ทำแล้ว
A4: 3 | B4: รัน Playwright ทุก spec ผ่าน Edge ตาม config จริง | C4: 179 tests ตามสถิติผ่านทั้งหมด แต่ 2 ใน 179 เป็นกรณีที่ทำเครื่องหมาย “คาดว่าล้มเหลว” (บั๊ก BUG-04, BUG-05 ยังอยู่) | D4: ทำแล้ว
A5: 4 | B5: อ่านยอด/ความสัมพันธ์/constraints/รูปของฐาน local จริงแบบไม่เขียน | C5: data-quality (READ ONLY) + OP-01..21: session ฐานข้อมูลบังคับ read-only ยอดก่อน/หลังเท่ากัน พบประกาศไม่มีผู้แจ้ง 12 รายการ และไม่มีเจ้าหน้าที่/ผู้ดูแลที่เปิดใช้ | D5: ทำแล้ว
A6: 5 | B6: ทดสอบ startup/API/persistence ด้วย PostgreSQL ชั่วคราวแยก | C6: 153 tests ผ่านทั้งหมด สร้างฐาน foundlost_test_<random> 4 ฐานและลบหลังจบ ยอดฐานจริงก่อน/หลังไม่เปลี่ยน (เครื่องมือ auto-test แสดง BLOCKED เพราะอ่านผลแบบ TAP ไม่ได้ ไม่ใช่ติดข้อจำกัดจริง) | D6: ทำแล้ว
A7: 6 | B7: วัด performance เบื้องต้นแบบ bounded ในฐานแยก | C7: OP-17: /health 20 ครั้ง สูงสุด 19 ms เฉลี่ย 13 ms (ไม่ใช่ load test) ไม่ได้รัน test/performance.cjs เพราะใช้ backend/.env ซึ่งชี้ฐานจริง | D7: ทำบางส่วน
A8: 7 | B8: รวมผลราย test case พร้อมหลักฐาน ไม่ข้ามกรณีล้มเหลว | C8: ชีต Test Cases (เอกสาร) ครบ 436 กรณี + ชีต User Manual + ชีตผลที่ไม่อยู่ในเอกสาร | D8: ทำแล้ว
A9: ความปลอดภัย | B9: ไม่เปิดเผยรหัสผ่าน/token/ข้อมูลจริง ไม่ส่งอีเมลจริง ไม่รัน migration กับฐานจริง | C9: ปฏิบัติตามทั้งหมด: ใช้บัญชีสังเคราะห์ ดักอีเมลไว้ ไม่เขียนฐานจริง | D9: ทำแล้ว

Sheet ผลที่ไม่อยู่ในเอกสาร
A1: ชุดทดสอบ | B1: ชื่อ test | C1: สถานะ | D1: หมายเหตุ
A2: Playwright/Edge | B2: item detail text meets WCAG AA colour contrast | C2: Fail (TODO) | D2: BUG-05: สีตัวอักษรหน้ารายละเอียดต่ำกว่า 4.5:1
A3: Playwright/Edge | B3: unknown URLs show a not-found page with a way back | C3: Fail (TODO) | D3: BUG-04: ไม่มี route สำหรับ URL ที่ไม่รู้จัก หน้าเว็บว่าง
A4: Node unit/integration (PGlite) | B4: API-DETAIL-01 item detail validates the id, requires login and returns 404 for unknown ids | C4: Pass
A5: Node unit/integration (PGlite) | B5: API-DETAIL-02 only the owner sees coordinates; nobody receives private details or student id | C5: Pass
A6: Node unit/integration (PGlite) | B6: API-HIST-01 history requires login and lists only the caller's own reports | C6: Pass
A7: Node unit/integration (PGlite) | B7: API-HIST-02 the owner's history shows their own private details decrypted; others never see them | C7: Pass
A8: Node unit/integration (PGlite) | B8: API-ITEM-01 creating a report requires a signed-in session | C8: Pass
A9: Node unit/integration (PGlite) | B9: API-ITEM-02 valid lost and found reports with a photo return 201 and keep the photo | C9: Pass
A10: Node unit/integration (PGlite) | B10: API-ITEM-03 invalid report fields are rejected with 400 and the uploaded photo is removed | C10: Pass
A11: Node unit/integration (PGlite) | B11: API-ITEM-04 boundary values are accepted (255-char name, leap day, 23:59, geographic extremes) | C11: Pass
A12: Node unit/integration (PGlite) | B12: API-ITEM-05 found reports require an active collection point | C12: Pass
A13: Node unit/integration (PGlite) | B13: API-ITEM-06 unsupported or spoofed images are rejected with 400 | C13: Pass
A14: Node unit/integration (PGlite) | B14: API-ITEM-07 photos larger than 5 MB are rejected with 400 | C14: Pass
A15: Node unit/integration (PGlite) | B15: API-ITEM-10 a lost/found date in the future is rejected | C15: Pass
... A101: PostgreSQL ฐานชั่วคราว | B101: unlisted and inactive emails cannot request setup/reset OTP or create accounts through legacy grants | C101: Pass

Sheet ข้อค้นพบ
A1: หมวด | B1: อ้างอิง | C1: สิ่งที่พบ | D1: ระดับ | E1: สิ่งที่ควรทำ
A2: ข้อมูลจริง | B2: OP-03 / DATA-OWNERS | C2: ประกาศของหาย 7 และของพบ 5 รายการในฐานจริงไม่มีผู้แจ้ง (student_id ว่าง) | D2: สูง | E2: ต้องหา mapping ผู้แจ้งที่ยืนยันได้ ห้ามสุ่มผูกบัญชี
A3: ข้อมูลจริง | B3: OP-04 | C3: ฐานจริงมีเฉพาะนิสิต 59 บัญชี ไม่มีเจ้าหน้าที่ที่เปิดใช้งานและไม่มีผู้ดูแล (admin) ที่เปิดใช้งาน และไม่มีจุดรับฝาก (0) | D3: สูง | E3: สร้าง/เปิดใช้บัญชีเจ้าหน้าที่และผู้ดูแล และเพิ่มจุดรับฝากก่อนใช้งานจริง
A4: คู่มือ | B4: UM-15 | C4: คู่มือบอกว่าเพิ่มจุดฝากโดยเลือกหมุด/ค้นหาจากแผนที่ได้ แต่ฟอร์มไม่มีแผนที่ | D4: กลาง | E4: เพิ่มแผนที่ในฟอร์ม หรือแก้คู่มือ
A5: คู่มือ | B5: UM-17 | C5: ทำตามคู่มือ (สลับภาษา) แล้วค่าในฟอร์มแจ้งหายหาย เพราะปุ่มภาษาอยู่ในหน้าโปรไฟล์ | D5: กลาง | E5: เพิ่มปุ่มภาษาในหน้าฟอร์ม/เก็บร่าง หรือแก้คู่มือ
A6: คู่มือ | B6: UM-01, 02, 06, 08, 09, 16 | C6: ชื่อปุ่ม/ข้อความในคู่มือไม่ตรงหน้าจอ และคู่มือบอกให้กรอกรหัสนิสิต ชื่อ นามสกุลตอนสมัคร ซึ่งหน้าจอไม่มี | D6: ต่ำ | E6: อัปเดต USER_MANUAL.md ให้ตรงหน้าจอปัจจุบัน
A7: บั๊กเดิม | B7: BUG-01 | C7: ส่งรูปผิดชื่อฟิลด์หรือหลายรูปได้ HTTP 500 แทน 4xx (TODO ใน qa-items-api) | D7: ต่ำ | E7: แปลง error ของ multer เป็น 400
A8: บั๊กเดิม | B8: BUG-03 | C8: อักขระ % และ _ ในช่องค้นหาไม่ถูก escape | D8: ต่ำ | E8: escape ก่อนใช้ใน ILIKE
A9: บั๊กเดิม | B9: BUG-04 | C9: URL ที่ไม่รู้จักแสดงหน้าเว็บว่าง | D9: ต่ำ | E9: เพิ่ม route * พร้อมลิงก์กลับ
A10: บั๊กเดิม | B10: BUG-05 | C10: สีตัวอักษรหน้ารายละเอียดสิ่งของต่ำกว่าเกณฑ์ WCAG AA | D10: กลาง | E10: ปรับสีใน ItemDetail.css
A11: PDPA | B11: EXT-03 / ประกาศ | C11: ยังไม่ตั้งชื่อ/อีเมลผู้ควบคุมข้อมูล และยังไม่อนุมัติประกาศความเป็นส่วนตัว | D11: สูง | E11: ให้ผู้มีอำนาจกำหนดและอนุมัติ
A12: เครื่องมือทดสอบ | B12: auto-test postgres | C12: tools/auto-test.cjs รายงาน postgres เป็น BLOCKED ทั้งที่รันผ่าน 153/153 เพราะอ่านผลแบบ TAP แต่ Node พิมพ์แบบ spec | D12: ต่ำ | E12: ส่ง --test-reporter=tap ให้ขั้น unit/postgres
A13: ดีขึ้นจากเอกสาร | B13: OP-06, OP-19, QA-04 | C13: เดิม FAIL (รูปหาย 2 ไฟล์, CORS ตอบ 500, dependency high 2 รายการ) รอบนี้ผ่านทั้งหมด | D13: - | E13: -
