Workbook

Sheet สรุปผล
A1: KU Lost & Found (FOUNDLOST) — สรุปผลการทดสอบ
A3: ระบบ | B3: KU Lost & Found — ระบบแจ้งของหาย/ของพบ
A4: อ้างอิงข้อกำหนด | B4: docs/REQUIREMENTS_BASELINE.md (FR-01 ถึง FR-15, NFR)
A5: รอบการทดสอบ | B5: Round 1
A6: สภาพแวดล้อม | B6: ฐานข้อมูลทดสอบแยกในหน่วยความจำ (PGlite) + Microsoft Edge (Playwright) บน Windows 10 — ไม่แตะฐานข้อมูลจริง ไม่ส่งอีเมลจริง
A7: ผู้ทดสอบ | B7: Claude (ทดสอบอัตโนมัติ)
A8: วันที่เริ่ม / สิ้นสุด | B8: 25/10/2026
A11: Requirement | B11: ทั้งหมด | C11: Pass | D11: Fail | E11: Blocked | F11: Not Run | G11: % ผ่าน
A12: FR-01 | B12: =COUNTIF('Test Cases'!$B$2:$B$283,A12) | C12: =COUNTIFS('Test Cases'!$B$2:$B$283,$A12,'Test Cases'!$J$2:$J$283,"Pass") | D12: =COUNTIFS('Test Cases'!$B$2:$B$283,$A12,'Test Cases'!$J$2:$J$283,"Fail") | E12: =COUNTIFS('Test Cases'!$B$2:$B$283,$A12,'Test Cases'!$J$2:$J$283,"Blocked") | F12: =COUNTIFS('Test Cases'!$B$2:$B$283,$A12,'Test Cases'!$J$2:$J$283,"Not Run") | G12: =IF((C12+D12)=0,"-",C12/(C12+D12))
A13: FR-02 | B13: =COUNTIF('Test Cases'!$B$2:$B$283,A13) | C13: =COUNTIFS('Test Cases'!$B$2:$B$283,$A13,'Test Cases'!$J$2:$J$283,"Pass") | D13: =COUNTIFS('Test Cases'!$B$2:$B$283,$A13,'Test Cases'!$J$2:$J$283,"Fail") | E13: =COUNTIFS('Test Cases'!$B$2:$B$283,$A13,'Test Cases'!$J$2:$J$283,"Blocked") | F13: =COUNTIFS('Test Cases'!$B$2:$B$283,$A13,'Test Cases'!$J$2:$J$283,"Not Run") | G13: =IF((C13+D13)=0,"-",C13/(C13+D13))
A14: FR-03 | B14: =COUNTIF('Test Cases'!$B$2:$B$283,A14) | C14: =COUNTIFS('Test Cases'!$B$2:$B$283,$A14,'Test Cases'!$J$2:$J$283,"Pass") | D14: =COUNTIFS('Test Cases'!$B$2:$B$283,$A14,'Test Cases'!$J$2:$J$283,"Fail") | E14: =COUNTIFS('Test Cases'!$B$2:$B$283,$A14,'Test Cases'!$J$2:$J$283,"Blocked") | F14: =COUNTIFS('Test Cases'!$B$2:$B$283,$A14,'Test Cases'!$J$2:$J$283,"Not Run") | G14: =IF((C14+D14)=0,"-",C14/(C14+D14))
A15: FR-04 | B15: =COUNTIF('Test Cases'!$B$2:$B$283,A15) | C15: =COUNTIFS('Test Cases'!$B$2:$B$283,$A15,'Test Cases'!$J$2:$J$283,"Pass") | D15: =COUNTIFS('Test Cases'!$B$2:$B$283,$A15,'Test Cases'!$J$2:$J$283,"Fail") | E15: =COUNTIFS('Test Cases'!$B$2:$B$283,$A15,'Test Cases'!$J$2:$J$283,"Blocked") | F15: =COUNTIFS('Test Cases'!$B$2:$B$283,$A15,'Test Cases'!$J$2:$J$283,"Not Run") | G15: =IF((C15+D15)=0,"-",C15/(C15+D15))
A16: FR-05 | B16: =COUNTIF('Test Cases'!$B$2:$B$283,A16) | C16: =COUNTIFS('Test Cases'!$B$2:$B$283,$A16,'Test Cases'!$J$2:$J$283,"Pass") | D16: =COUNTIFS('Test Cases'!$B$2:$B$283,$A16,'Test Cases'!$J$2:$J$283,"Fail") | E16: =COUNTIFS('Test Cases'!$B$2:$B$283,$A16,'Test Cases'!$J$2:$J$283,"Blocked") | F16: =COUNTIFS('Test Cases'!$B$2:$B$283,$A16,'Test Cases'!$J$2:$J$283,"Not Run") | G16: =IF((C16+D16)=0,"-",C16/(C16+D16))
A17: FR-06 | B17: =COUNTIF('Test Cases'!$B$2:$B$283,A17) | C17: =COUNTIFS('Test Cases'!$B$2:$B$283,$A17,'Test Cases'!$J$2:$J$283,"Pass") | D17: =COUNTIFS('Test Cases'!$B$2:$B$283,$A17,'Test Cases'!$J$2:$J$283,"Fail") | E17: =COUNTIFS('Test Cases'!$B$2:$B$283,$A17,'Test Cases'!$J$2:$J$283,"Blocked") | F17: =COUNTIFS('Test Cases'!$B$2:$B$283,$A17,'Test Cases'!$J$2:$J$283,"Not Run") | G17: =IF((C17+D17)=0,"-",C17/(C17+D17))
A18: FR-07 | B18: =COUNTIF('Test Cases'!$B$2:$B$283,A18) | C18: =COUNTIFS('Test Cases'!$B$2:$B$283,$A18,'Test Cases'!$J$2:$J$283,"Pass") | D18: =COUNTIFS('Test Cases'!$B$2:$B$283,$A18,'Test Cases'!$J$2:$J$283,"Fail") | E18: =COUNTIFS('Test Cases'!$B$2:$B$283,$A18,'Test Cases'!$J$2:$J$283,"Blocked") | F18: =COUNTIFS('Test Cases'!$B$2:$B$283,$A18,'Test Cases'!$J$2:$J$283,"Not Run") | G18: =IF((C18+D18)=0,"-",C18/(C18+D18))
A19: FR-08 | B19: =COUNTIF('Test Cases'!$B$2:$B$283,A19) | C19: =COUNTIFS('Test Cases'!$B$2:$B$283,$A19,'Test Cases'!$J$2:$J$283,"Pass") | D19: =COUNTIFS('Test Cases'!$B$2:$B$283,$A19,'Test Cases'!$J$2:$J$283,"Fail") | E19: =COUNTIFS('Test Cases'!$B$2:$B$283,$A19,'Test Cases'!$J$2:$J$283,"Blocked") | F19: =COUNTIFS('Test Cases'!$B$2:$B$283,$A19,'Test Cases'!$J$2:$J$283,"Not Run") | G19: =IF((C19+D19)=0,"-",C19/(C19+D19))
A20: FR-09 | B20: =COUNTIF('Test Cases'!$B$2:$B$283,A20) | C20: =COUNTIFS('Test Cases'!$B$2:$B$283,$A20,'Test Cases'!$J$2:$J$283,"Pass") | D20: =COUNTIFS('Test Cases'!$B$2:$B$283,$A20,'Test Cases'!$J$2:$J$283,"Fail") | E20: =COUNTIFS('Test Cases'!$B$2:$B$283,$A20,'Test Cases'!$J$2:$J$283,"Blocked") | F20: =COUNTIFS('Test Cases'!$B$2:$B$283,$A20,'Test Cases'!$J$2:$J$283,"Not Run") | G20: =IF((C20+D20)=0,"-",C20/(C20+D20))
A21: FR-10 | B21: =COUNTIF('Test Cases'!$B$2:$B$283,A21) | C21: =COUNTIFS('Test Cases'!$B$2:$B$283,$A21,'Test Cases'!$J$2:$J$283,"Pass") | D21: =COUNTIFS('Test Cases'!$B$2:$B$283,$A21,'Test Cases'!$J$2:$J$283,"Fail") | E21: =COUNTIFS('Test Cases'!$B$2:$B$283,$A21,'Test Cases'!$J$2:$J$283,"Blocked") | F21: =COUNTIFS('Test Cases'!$B$2:$B$283,$A21,'Test Cases'!$J$2:$J$283,"Not Run") | G21: =IF((C21+D21)=0,"-",C21/(C21+D21))
A22: FR-11 | B22: =COUNTIF('Test Cases'!$B$2:$B$283,A22) | C22: =COUNTIFS('Test Cases'!$B$2:$B$283,$A22,'Test Cases'!$J$2:$J$283,"Pass") | D22: =COUNTIFS('Test Cases'!$B$2:$B$283,$A22,'Test Cases'!$J$2:$J$283,"Fail") | E22: =COUNTIFS('Test Cases'!$B$2:$B$283,$A22,'Test Cases'!$J$2:$J$283,"Blocked") | F22: =COUNTIFS('Test Cases'!$B$2:$B$283,$A22,'Test Cases'!$J$2:$J$283,"Not Run") | G22: =IF((C22+D22)=0,"-",C22/(C22+D22))
A23: FR-12 | B23: =COUNTIF('Test Cases'!$B$2:$B$283,A23) | C23: =COUNTIFS('Test Cases'!$B$2:$B$283,$A23,'Test Cases'!$J$2:$J$283,"Pass") | D23: =COUNTIFS('Test Cases'!$B$2:$B$283,$A23,'Test Cases'!$J$2:$J$283,"Fail") | E23: =COUNTIFS('Test Cases'!$B$2:$B$283,$A23,'Test Cases'!$J$2:$J$283,"Blocked") | F23: =COUNTIFS('Test Cases'!$B$2:$B$283,$A23,'Test Cases'!$J$2:$J$283,"Not Run") | G23: =IF((C23+D23)=0,"-",C23/(C23+D23))
... A27: NFR | B27: =COUNTIF('Test Cases'!$B$2:$B$283,A27) | C27: =COUNTIFS('Test Cases'!$B$2:$B$283,$A27,'Test Cases'!$J$2:$J$283,"Pass") | D27: =COUNTIFS('Test Cases'!$B$2:$B$283,$A27,'Test Cases'!$J$2:$J$283,"Fail") | E27: =COUNTIFS('Test Cases'!$B$2:$B$283,$A27,'Test Cases'!$J$2:$J$283,"Blocked") | F27: =COUNTIFS('Test Cases'!$B$2:$B$283,$A27,'Test Cases'!$J$2:$J$283,"Not Run") | G27: =IF((C27+D27)=0,"-",C27/(C27+D27))
A28: รวม | B28: =SUM(B12:B27) | C28: =SUM(C12:C27) | D28: =SUM(D12:D27) | E28: =SUM(E12:E27) | F28: =SUM(F12:F27) | G28: =IF((C28+D28)=0,"-",C28/(C28+D28))
A30: % ผ่าน = Pass ÷ (Pass + Fail) ของกรณีที่รันแล้ว — ตัวเลขทุกช่องคำนวณอัตโนมัติจากชีต Test Cases
A32: ผู้ทดสอบ: ______________________ วันที่: ____________
A34: ผู้ตรวจสอบ: ______________________ วันที่: ____________
A36: ผู้อนุมัติ: ______________________ วันที่: ____________

Sheet Test Cases
A1: Test Case ID | B1: Requirement | C1: โมดูล | D1: หัวข้อทดสอบ (Scenario) | E1: เงื่อนไขก่อนทดสอบ | F1: ขั้นตอนการทดสอบ | G1: ข้อมูลทดสอบ | H1: ผลที่คาดหวัง | I1: ผลจริง | J1: สถานะ | K1: ความสำคัญ | L1: ประเภท | M1: ผู้ทดสอบ | N1: วันที่ทดสอบ | O1: Bug ID / หมายเหตุ
A2: TC-FR01-01 | B2: FR-01 | C2: เข้าสู่ระบบ | D2: ขอ OTP ด้วยอีเมล @ku.th ที่อยู่ในทะเบียน | E2: บัญชี active อยู่ในตาราง users ยังไม่เคยตั้งรหัสผ่าน | F2: 1. เปิดหน้า Login 2. กรอกอีเมล 3. กด ขอรหัส OTP | G2: อีเมล: student01@ku.th | H2: ระบบแจ้งว่าส่ง OTP แล้ว ได้รับอีเมล OTP 6 หลัก | I2: HTTP 200 — ได้อีเมล OTP 6 หลัก: ใช่ | J2: Pass | K2: High | L2: Positive | M2: Claude (ทดสอบอัตโนมัติ) | N2: 46320
A3: TC-FR01-02 | B3: FR-01 | C3: เข้าสู่ระบบ | D3: ขอ OTP ด้วยอีเมลที่ไม่ใช่ @ku.th | E3: - | F3: 1. เปิดหน้า Login 2. กรอกอีเมลนอกโดเมน 3. กด ขอรหัส OTP | G3: อีเมล: test@gmail.com | H3: ระบบปฏิเสธ แสดงข้อความให้ใช้อีเมล @ku.th ไม่ส่ง OTP | I3: HTTP 400 “ใช้อีเมล @ku.th เท่านั้น” — ไม่มีการส่ง OTP | J3: Pass | K3: High | L3: Negative | M3: Claude (ทดสอบอัตโนมัติ) | N3: 46320
A4: TC-FR01-03 | B4: FR-01 | C4: เข้าสู่ระบบ | D4: ขอ OTP ด้วยอีเมล @ku.th ที่ไม่มีในทะเบียน | E4: อีเมลไม่มีในตาราง users | F4: 1. กรอกอีเมล 2. กด ขอรหัส OTP | G4: อีเมล: nobody@ku.th | H4: ไม่ส่ง OTP และแสดงข้อความชัดเจนว่าไม่พบอีเมลนี้ในทะเบียนที่อนุญาต หรือบัญชีถูกระงับ ให้ติดต่อผู้ดูแลระบบ (ออกแบบให้แจ้งชัดตาม README) | I4: รอบ 5 (หลังแก้ผลที่คาดหวัง): HTTP 403 “ไม่พบอีเมลนี้ในทะเบียนที่อนุญาต หรือบัญชีถูกระงับ กรุณาติดต่อผู้ดูแลระบบ” ไม่ส่ง OTP รอบ 1: ผลเดียวกัน แต่ผลที่คาดหวังเดิมกำหนดให้ไม่เปิดเผยว่าอีเมลมีในระบบหรือไม่ | J4: Pass | K4: High | L4: Negative | M4: Claude (ทดสอบอัตโนมัติ) | N4: 46320 | O4: เจ้าของโปรเจกต์ยืนยันให้คงข้อความแจ้งชัดตามที่ออกแบบไว้ จึงแก้ผลที่คาดหวัง (ไม่ได้แก้โค้ด)
A5: TC-FR01-04 | B5: FR-01 | C5: เข้าสู่ระบบ | D5: ขอ OTP ด้วยบัญชีที่ถูกปิดใช้งาน | E5: บัญชีสถานะ inactive | F5: 1. กรอกอีเมลบัญชี inactive 2. กด ขอรหัส OTP | G5: อีเมล: inactive01@ku.th | H5: ไม่ส่ง OTP และเข้าใช้ไม่ได้ | I5: HTTP 403 “ไม่พบอีเมลนี้ในทะเบียนที่อนุญาต หรือบัญชีถูกระงับ กรุณาติดต่อผู้ดูแลระบบ” — ไม่ส่ง OTP | J5: Pass | K5: High | L5: Negative | M5: Claude (ทดสอบอัตโนมัติ) | N5: 46320
A6: TC-FR01-05 | B6: FR-01 | C6: เข้าสู่ระบบ | D6: ยืนยัน OTP ถูกต้องภายในเวลา | E6: ได้รับ OTP แล้ว (อายุ 5 นาที) | F6: 1. กรอก OTP ที่ได้รับ 2. กด ยืนยัน | G6: OTP: ตามอีเมล | H6: ยืนยันสำเร็จ ไปหน้าตั้งรหัสผ่าน | I6: HTTP 200 — ได้สิทธิ์ตั้งรหัสผ่าน (setupToken) | J6: Pass | K6: High | L6: Positive | M6: Claude (ทดสอบอัตโนมัติ) | N6: 46320
A7: TC-FR01-06 | B7: FR-01 | C7: เข้าสู่ระบบ | D7: ยืนยัน OTP ผิด | E7: ได้รับ OTP แล้ว | F7: 1. กรอก OTP ผิด 2. กด ยืนยัน | G7: OTP: 000000 | H7: แสดงข้อความ OTP ไม่ถูกต้อง ไม่เข้าสู่ระบบ | I7: HTTP 400 “OTP ไม่ถูกต้อง หมดอายุ หรือเกินจำนวนครั้ง” | J7: Pass | K7: High | L7: Negative | M7: Claude (ทดสอบอัตโนมัติ) | N7: 46320
A8: TC-FR01-07 | B8: FR-01 | C8: เข้าสู่ระบบ | D8: กรอก OTP ผิดเกิน 5 ครั้ง | E8: ได้รับ OTP แล้ว | F8: 1. กรอก OTP ผิด 5 ครั้ง 2. ครั้งที่ 6 กรอก OTP ที่ถูกต้อง | G8: OTP ผิด x5 แล้ว OTP ถูก | H8: OTP ถูกล็อก ต้องขอ OTP ใหม่ แม้ครั้งที่ 6 กรอกถูก | I8: ผิด 5 ครั้งแล้วกรอก OTP ถูก: HTTP 400 “OTP ไม่ถูกต้อง หมดอายุ หรือเกินจำนวนครั้ง” — ถูกล็อก | J8: Pass | K8: High | L8: Boundary | M8: Claude (ทดสอบอัตโนมัติ) | N8: 46320
A9: TC-FR01-08 | B9: FR-01 | C9: เข้าสู่ระบบ | D9: ใช้ OTP ที่หมดอายุ (เกิน 5 นาที) | E9: ได้รับ OTP แล้วรอเกิน 5 นาที | F9: 1. รอ 5 นาทีขึ้นไป 2. กรอก OTP 3. กด ยืนยัน | G9: OTP: ตามอีเมล | H9: แจ้งว่า OTP หมดอายุ ให้ขอใหม่ | I9: ตั้งเวลา OTP ให้เลย 5 นาที: HTTP 400 “OTP ไม่ถูกต้อง หมดอายุ หรือเกินจำนวนครั้ง” | J9: Pass | K9: High | L9: Boundary | M9: Claude (ทดสอบอัตโนมัติ) | N9: 46320
A10: TC-FR01-09 | B10: FR-01 | C10: เข้าสู่ระบบ | D10: OTP ต้องเป็นตัวเลข 6 หลัก | E10: อยู่หน้ากรอก OTP | F10: 1. กรอก OTP 5 หลัก / มีตัวอักษร 2. กด ยืนยัน | G10: 12345, 12a456 | H10: ฟอร์มไม่ยอมให้ส่ง หรือแจ้งรูปแบบไม่ถูกต้อง | I10: 12345: HTTP 400 “กรอกรหัส OTP 6 หลัก” / 12a456: HTTP 400 “กรอกรหัส OTP 6 หลัก” | J10: Pass | K10: Medium | L10: Negative | M10: Claude (ทดสอบอัตโนมัติ) | N10: 46320
A11: TC-FR01-10 | B11: FR-01 | C11: เข้าสู่ระบบ | D11: ขอ OTP ถี่เกินกำหนด (rate limit) | E11: - | F11: 1. กด ขอ OTP ซ้ำ 6 ครั้งภายใน 15 นาที | G11: อีเมลเดิม | H11: ครั้งที่เกินถูกปฏิเสธ แจ้งให้รอแล้วลองใหม่ | I11: สถานะ 6 ครั้ง: 200, 429, 429, 429, 429, 429 (ครั้งที่ 2 เป็นต้นไปถูกปฏิเสธเพราะต้องรอ 60 วินาที) | J11: Pass | K11: Medium | L11: Security | M11: Claude (ทดสอบอัตโนมัติ) | N11: 46320
A12: TC-FR01-11 | B12: FR-01 | C12: เข้าสู่ระบบ | D12: ตั้งรหัสผ่านยาว 15 ตัวอักษร (ขอบล่าง) | E12: ยืนยัน OTP สำเร็จ | F12: 1. กรอกรหัสผ่าน 15 ตัว และยืนยัน 2. กด บันทึก | G12: รหัส 15 ตัวอักษร | H12: บันทึกสำเร็จ เข้าสู่ระบบได้ | I12: รหัส 16 ตัว: HTTP 200 — ได้ session เข้าสู่ระบบ | J12: Pass | K12: High | L12: Boundary | M12: Claude (ทดสอบอัตโนมัติ) | N12: 46320
A13: TC-FR01-12 | B13: FR-01 | C13: เข้าสู่ระบบ | D13: ตั้งรหัสผ่านสั้นกว่า 15 ตัวอักษร | E13: ยืนยัน OTP สำเร็จ | F13: 1. กรอกรหัสผ่าน 14 ตัว 2. กด บันทึก | G13: รหัส 14 ตัวอักษร | H13: แสดง “รหัสผ่านต้องยาว 15–128 ตัวอักษร” ไม่บันทึก | I13: HTTP 400 “รหัสผ่านต้องยาว 15–128 ตัวอักษร” | J13: Pass | K13: High | L13: Boundary | M13: Claude (ทดสอบอัตโนมัติ) | N13: 46320
A14: TC-FR01-13 | B14: FR-01 | C14: เข้าสู่ระบบ | D14: ตั้งรหัสผ่านยาวเกิน 128 ตัวอักษร | E14: ยืนยัน OTP สำเร็จ | F14: 1. กรอกรหัสผ่าน 129 ตัว 2. กด บันทึก | G14: รหัส 129 ตัวอักษร | H14: ไม่บันทึก แจ้งความยาวไม่ถูกต้อง | I14: HTTP 400 “รหัสผ่านต้องยาว 15–128 ตัวอักษร” | J14: Pass | K14: Medium | L14: Boundary | M14: Claude (ทดสอบอัตโนมัติ) | N14: 46320
A15: TC-FR01-14 | B15: FR-01 | C15: เข้าสู่ระบบ | D15: รหัสผ่านและยืนยันรหัสผ่านไม่ตรงกัน | E15: ยืนยัน OTP สำเร็จ | F15: 1. กรอกรหัสผ่านสองช่องไม่ตรงกัน 2. กด บันทึก | G15: - | H15: แจ้งรหัสผ่านไม่ตรงกัน ไม่บันทึก | I15: กรอกรหัสผ่านสองช่องไม่ตรงกันแล้วกดบันทึก: หน้าเว็บแสดง “รหัสผ่านทั้งสองช่องไม่ตรงกัน” และยังอยู่หน้าตั้งรหัสผ่าน ไม่บันทึก | J15: Pass | K15: Medium | L15: Negative | M15: Claude (ทดสอบอัตโนมัติ) | N15: 46320 | O15: ทดสอบบน Microsoft Edge; ภาพหน้าจอ TC-FR01-14.png
A16: TC-FR01-15 | B16: FR-01 | C16: เข้าสู่ระบบ | D16: เข้าสู่ระบบด้วยรหัสผ่านถูกต้อง | E16: ตั้งรหัสผ่านแล้ว | F16: 1. กรอกอีเมลและรหัสผ่าน 2. กด เข้าสู่ระบบ | G16: อีเมล + รหัสผ่านที่ตั้งไว้ | H16: เข้าสู่ระบบสำเร็จ ไปหน้าหลัก แสดงชื่อผู้ใช้ | I16: HTTP 200 — ได้ชื่อผู้ใช้ Somchai | J16: Pass | K16: High | L16: Positive | M16: Claude (ทดสอบอัตโนมัติ) | N16: 46320
A17: TC-FR01-16 | B17: FR-01 | C17: เข้าสู่ระบบ | D17: เข้าสู่ระบบด้วยรหัสผ่านผิด | E17: ตั้งรหัสผ่านแล้ว | F17: 1. กรอกรหัสผ่านผิด 2. กด เข้าสู่ระบบ | G17: รหัสผ่านผิด | H17: แจ้งอีเมลหรือรหัสผ่านไม่ถูกต้อง ไม่ระบุว่าผิดช่องใด | I17: HTTP 401 “ชื่อผู้ใช้/อีเมลหรือรหัสผ่านไม่ถูกต้อง หรือบัญชีถูกระงับ” — ข้อความเหมือนกรณีอีเมลไม่มีในระบบ | J17: Pass | K17: High | L17: Negative | M17: Claude (ทดสอบอัตโนมัติ) | N17: 46320
A18: TC-FR01-17 | B18: FR-01 | C18: เข้าสู่ระบบ | D18: เข้าสู่ระบบโดยเว้นช่องว่าง | E18: - | F18: 1. ไม่กรอกอีเมล/รหัสผ่าน 2. กด เข้าสู่ระบบ | G18: ว่าง | H18: แจ้งให้กรอกข้อมูลที่จำเป็น | I18: HTTP 400 “ชื่อผู้ใช้หรืออีเมลไม่ถูกต้อง” | J18: Pass | K18: Low | L18: Negative | M18: Claude (ทดสอบอัตโนมัติ) | N18: 46320
A19: TC-FR01-18 | B19: FR-01 | C19: เข้าสู่ระบบ | D19: ลืมรหัสผ่าน (Reset ผ่าน OTP) | E19: ตั้งรหัสผ่านแล้ว | F19: 1. กด ลืมรหัสผ่าน 2. ขอ OTP และยืนยัน 3. ตั้งรหัสผ่านใหม่ 4. Login ด้วยรหัสใหม่ | G19: รหัสใหม่ 15+ ตัว | H19: เปลี่ยนรหัสสำเร็จ รหัสเดิมใช้ไม่ได้ รหัสใหม่ใช้ได้ | I19: ตั้งรหัสใหม่ 200; รหัสเดิม 401; รหัสใหม่ 200 | J19: Pass | K19: High | L19: Positive | M19: Claude (ทดสอบอัตโนมัติ) | N19: 46320
A20: TC-FR01-19 | B20: FR-01 | C20: เข้าสู่ระบบ | D20: ออกจากระบบ (Logout) | E20: เข้าสู่ระบบอยู่ | F20: 1. กด ออกจากระบบ 2. กด Back ของเบราว์เซอร์ / เปิดหน้าที่ต้อง Login | G20: - | H20: กลับหน้า Login เปิดหน้าที่ต้อง Login ไม่ได้ | I20: ก่อน logout 200; logout 200; หลัง logout 401 | J20: Pass | K20: High | L20: Positive | M20: Claude (ทดสอบอัตโนมัติ) | N20: 46320
A21: TC-FR01-20 | B21: FR-01 | C21: เข้าสู่ระบบ | D21: Session หมดอายุ (7 วัน) | E21: เข้าสู่ระบบไว้เกิน 7 วัน หรือแก้วันหมดอายุ session ในฐานทดสอบ | F21: 1. เปิดหน้าใดก็ได้ที่ต้อง Login | G21: - | H21: ระบบให้ Login ใหม่ | I21: ตั้งเวลา session ให้หมดอายุ: HTTP 401 “Session expired, inactive or invalid” | J21: Pass | K21: Medium | L21: Boundary | M21: Claude (ทดสอบอัตโนมัติ) | N21: 46320
A22: TC-FR01-21 | B22: FR-01 | C22: เข้าสู่ระบบ | D22: เข้าสู่ระบบด้วย Google @ku.th | E22: ตั้ง Google OAuth Client ID แล้ว | F22: 1. กด เข้าสู่ระบบด้วย Google 2. เลือกบัญชี @ku.th | G22: บัญชี Google @ku.th | H22: เข้าสู่ระบบสำเร็จ (ถ้ายังไม่ตั้งค่า ปุ่มต้องไม่แสดง) | I22: จำลองการยืนยันจาก Google (ไม่ได้ใช้บัญชี Google จริง): HTTP 200 | J22: Pass | K22: Low | L22: Positive | M22: Claude (ทดสอบอัตโนมัติ) | N22: 46320 | O22: จำลองผลยืนยันจาก Google (ยังไม่ได้ทดสอบกับบัญชี Google จริง)
A23: TC-FR01-22 | B23: FR-01 | C23: เข้าสู่ระบบ | D23: เข้าสู่ระบบด้วย Google ที่ไม่ใช่ @ku.th | E23: ตั้ง Google OAuth Client ID แล้ว | F23: 1. กด เข้าสู่ระบบด้วย Google 2. เลือกบัญชี gmail | G23: บัญชี @gmail.com | H23: ระบบปฏิเสธ | I23: จำลอง Google @gmail.com: HTTP 403 “ใช้ได้เฉพาะบัญชี Google ของ KU (@ku.th)” | J23: Pass | K23: Medium | L23: Negative | M23: Claude (ทดสอบอัตโนมัติ) | N23: 46320
A24: TC-FR02-01 | B24: FR-02 | C24: แจ้งของหาย | D24: แจ้งของหายครบทุกช่องพร้อมรูป | E24: Login เป็นนิสิต | F24: 1. กด แจ้งของหาย 2. กรอกชื่อสิ่งของ ประเภท ยี่ห้อ รุ่น สี ลักษณะเฉพาะ วันเวลา สถานที่ 3. แนบรูป 4. กด ส่ง | G24: ชื่อ: กระเป๋าสตางค์ ประเภท: กระเป๋า สี: ดำ รูป: wallet.jpg (1 MB) | H24: บันทึกสำเร็จ รายการแสดงในหน้าของหายและประวัติของฉัน สถานะ รอดำเนินการ | I24: HTTP 201 item_id=1; สถานะ pending; มีรูป: true; อยู่ในรายการ+ประวัติของฉัน | J24: Pass | K24: High | L24: Positive | M24: Claude (ทดสอบอัตโนมัติ) | N24: 46320
A25: TC-FR02-02 | B25: FR-02 | C25: แจ้งของหาย | D25: แจ้งของหายเฉพาะช่องบังคับ ไม่แนบรูป | E25: Login เป็นนิสิต | F25: 1. กรอกเฉพาะช่องบังคับ 2. กด ส่ง | G25: ชื่อ: ร่ม | H25: บันทึกสำเร็จ | I25: HTTP 201 | J25: Pass | K25: Medium | L25: Positive | M25: Claude (ทดสอบอัตโนมัติ) | N25: 46320
A26: TC-FR02-03 | B26: FR-02 | C26: แจ้งของหาย | D26: ไม่กรอกชื่อสิ่งของ (ช่องบังคับ) | E26: Login เป็นนิสิต | F26: 1. เว้นชื่อสิ่งของ 2. กด ส่ง | G26: ชื่อ: ว่าง | H26: แจ้งให้กรอกชื่อสิ่งของ ไม่บันทึก | I26: HTTP 400 “item_name is required” | J26: Pass | K26: High | L26: Negative | M26: Claude (ทดสอบอัตโนมัติ) | N26: 46320
A27: TC-FR02-04 | B27: FR-02 | C27: แจ้งของหาย | D27: ชื่อสิ่งของยาว 255 / 256 ตัวอักษร | E27: Login เป็นนิสิต | F27: 1. กรอกชื่อ 255 ตัว → ส่ง 2. กรอกชื่อ 256 ตัว → ส่ง | G27: 255 และ 256 ตัวอักษร | H27: 255 ตัวบันทึกได้ / 256 ตัวถูกปฏิเสธ | I27: 255 ตัว: 201; 256 ตัว: HTTP 400 “item_name must not exceed 255 characters” | J27: Pass | K27: Medium | L27: Boundary | M27: Claude (ทดสอบอัตโนมัติ) | N27: 46320
A28: TC-FR02-05 | B28: FR-02 | C28: แจ้งของหาย | D28: รายละเอียดยาวเกิน 5,000 ตัวอักษร | E28: Login เป็นนิสิต | F28: 1. กรอกรายละเอียด 5,001 ตัว 2. กด ส่ง | G28: 5,001 ตัวอักษร | H28: ไม่บันทึก แจ้งความยาวเกิน | I28: HTTP 400 “description must not exceed 5000 characters” | J28: Pass | K28: Low | L28: Boundary | M28: Claude (ทดสอบอัตโนมัติ) | N28: 46320
A29: TC-FR02-06 | B29: FR-02 | C29: แจ้งของหาย | D29: แนบรูปชนิดไม่รองรับ | E29: Login เป็นนิสิต | F29: 1. แนบไฟล์ .gif หรือ .pdf 2. กด ส่ง | G29: file.pdf | H29: ปฏิเสธไฟล์ รองรับเฉพาะ JPG/PNG/WebP | I29: HTTP 400 “ใช้รูป JPG, PNG หรือ WebP เท่านั้น” | J29: Pass | K29: Medium | L29: Negative | M29: Claude (ทดสอบอัตโนมัติ) | N29: 46320
A30: TC-FR02-07 | B30: FR-02 | C30: แจ้งของหาย | D30: แนบรูปขนาดเกิน 5 MB | E30: Login เป็นนิสิต | F30: 1. แนบรูปขนาด 5.1 MB 2. กด ส่ง | G30: big.jpg (5.1 MB) | H30: ปฏิเสธ แจ้งไฟล์ใหญ่เกินกำหนด | I30: ไฟล์ 5.1 MB: HTTP 400 “File too large” | J30: Pass | K30: Medium | L30: Boundary | M30: Claude (ทดสอบอัตโนมัติ) | N30: 46320
A31: TC-FR02-08 | B31: FR-02 | C31: แจ้งของหาย | D31: ระบุวันที่หายเป็นอนาคต | E31: Login เป็นนิสิต | F31: 1. เลือกวันที่หายเป็นวันพรุ่งนี้ 2. กด ส่ง | G31: วันที่: พรุ่งนี้ | H31: ไม่ให้บันทึก หรือแจ้งเตือนวันที่ไม่ถูกต้อง | I31: รอบ 2 (หลังแก้): ส่งวันที่พรุ่งนี้ได้ HTTP 400 “lost_date must not be in the future” ไม่บันทึก; ช่องวันที่ในฟอร์มตั้ง max เป็นวันนี้ (เวลาไทย) รอบ 1: ระบบรับวันที่ในอนาคต (HTTP 201) | J31: Pass | K31: Medium | L31: Negative | M31: Claude (ทดสอบอัตโนมัติ) | N31: 46320 | O31: แก้ BUG-02 แล้วใน backend/validation.js และ ReportForm.jsx — รอบ 1 Fail, รอบ 2 Pass
A32: TC-FR02-09 | B32: FR-02 | C32: แจ้งของหาย | D32: เลือกสถานที่จากแผนที่ / รายการแนะนำ | E32: Login เป็นนิสิต | F32: 1. พิมพ์ชื่อสถานที่บางส่วน 2. เลือกจากรายการแนะนำ หรือปักหมุดบนแผนที่ | G32: สถานที่: อาคาร 15 | H32: บันทึกชื่อสถานที่และพิกัดถูกต้อง | I32: บันทึก: อาคาร 15 (13.8466, 100.5703) | J32: Pass | K32: Medium | L32: Positive | M32: Claude (ทดสอบอัตโนมัติ) | N32: 46320
A33: TC-FR02-10 | B33: FR-02 | C33: แจ้งของหาย | D33: ผู้ที่ไม่ได้ Login แจ้งของหาย | E33: ยังไม่ Login | F33: 1. เปิด URL หน้าแจ้งของหายโดยตรง | G33: - | H33: ถูกพาไปหน้า Login | I33: ไม่มี session: HTTP 401 “Session expired, inactive or invalid” | J33: Pass | K33: High | L33: Security | M33: Claude (ทดสอบอัตโนมัติ) | N33: 46320
A34: TC-FR03-01 | B34: FR-03 | C34: แจ้งของพบ | D34: แจ้งของพบพร้อมระบุจุดฝาก | E34: Login เป็นนิสิต | F34: 1. กด แจ้งของพบ 2. กรอกข้อมูล สถานที่พบ จุดฝาก 3. แนบรูป 4. กด ส่ง | G34: ชื่อ: บัตรนิสิต จุดฝาก: ตึกกิจการนิสิต | H34: บันทึกสำเร็จ แสดงในหน้าของพบ พร้อมจุดฝาก | I34: HTTP 201 item_id=1; รายการแสดงจุดฝาก | J34: Pass | K34: High | L34: Positive | M34: Claude (ทดสอบอัตโนมัติ) | N34: 46320
A35: TC-FR03-02 | B35: FR-03 | C35: แจ้งของพบ | D35: แจ้งของพบไม่ระบุจุดฝาก | E35: Login เป็นนิสิต | F35: 1. เว้นช่องจุดฝาก 2. กด ส่ง | G35: - | H35: ระบบบังคับ หรือแจ้งให้เลือกจุดฝาก ตามที่ออกแบบ | I35: ไม่ระบุจุดฝาก: HTTP 400 “กรุณาเลือกจุดรับฝากที่ถูกต้อง” — ไม่บันทึก | J35: Pass | K35: Medium | L35: Negative | M35: Claude (ทดสอบอัตโนมัติ) | N35: 46320
A36: TC-FR03-03 | B36: FR-03 | C36: แจ้งของพบ | D36: เจ้าหน้าที่อัปเดตจุดฝากปัจจุบัน | E36: Login เป็น Staff มีรายการของพบ | F36: 1. เปิดรายการของพบในหน้า Admin 2. เปลี่ยนจุดฝาก 3. บันทึก | G36: จุดฝากใหม่: สำนักหอสมุด | H36: จุดฝากเปลี่ยน แสดงผลใหม่ฝั่งผู้ใช้ มีบันทึก audit | I36: HTTP 200; จุดฝากใหม่: สำนักหอสมุด; audit 1 รายการ | J36: Pass | K36: High | L36: Positive | M36: Claude (ทดสอบอัตโนมัติ) | N36: 46320
A37: TC-FR03-04 | B37: FR-03 | C37: แจ้งของพบ | D37: นิสิตทั่วไปพยายามแก้จุดฝาก | E37: Login เป็นนิสิต | F37: 1. เรียก API แก้จุดฝากของรายการผู้อื่น | G37: - | H37: ได้ 403 Forbidden ข้อมูลไม่เปลี่ยน | I37: HTTP 401 “Staff or administrator authentication required”; ข้อมูลไม่เปลี่ยน | J37: Pass | K37: High | L37: Security | M37: Claude (ทดสอบอัตโนมัติ) | N37: 46320
A38: TC-FR04-01 | B38: FR-04 | C38: จับคู่อัตโนมัติ | D38: ของหาย-ของพบลักษณะตรงกันถูกจับคู่ | E38: มีรายการของหาย | F38: 1. แจ้งของพบประเภท สี สถานที่ และเวลาใกล้เคียงกับของหาย 2. รอระบบประมวลผล | G38: ของหาย/ของพบ: กระเป๋าสตางค์ดำ อาคาร 15 วันเดียวกัน | H38: ระบบสร้างคู่ แสดง confidence score สูง | I38: สร้างคู่ match_id=1 score=99.00 | J38: Pass | K38: High | L38: Positive | M38: Claude (ทดสอบอัตโนมัติ) | N38: 46320 | O38: จำลองผลเปรียบเทียบรูปเป็น 100 (ไม่ได้รันโมเดล vision จริง) — score รวม = 0.4×ข้อความ + 0.6×รูป, เกณฑ์ 95
A39: TC-FR04-02 | B39: FR-04 | C39: จับคู่อัตโนมัติ | D39: ของต่างประเภทไม่ถูกจับคู่ | E39: มีรายการของหาย | F39: 1. แจ้งของพบประเภทต่างกันสิ้นเชิง | G39: ของหาย: ร่ม / ของพบ: โทรศัพท์ | H39: ไม่สร้างคู่ หรือ score ต่ำกว่าเกณฑ์ | I39: ไม่สร้างคู่ระหว่างร่มกับโทรศัพท์ | J39: Pass | K39: High | L39: Negative | M39: Claude (ทดสอบอัตโนมัติ) | N39: 46320
A40: TC-FR04-03 | B40: FR-04 | C40: จับคู่อัตโนมัติ | D40: ช่วงเวลาห่างกันมากลดคะแนน | E40: มีรายการของหาย | F40: 1. แจ้งของพบลักษณะตรงกัน แต่วันที่ห่างหลายเดือน | G40: ห่าง 6 เดือน | H40: score ต่ำกว่ากรณีวันใกล้กัน | I40: วันเดียวกัน score=99.00; ห่าง 180 วัน score=95.30 | J40: Pass | K40: Medium | L40: Positive | M40: Claude (ทดสอบอัตโนมัติ) | N40: 46320 | O40: จำลองผลเปรียบเทียบรูปเช่นเดียวกับ TC-FR04-01
...

Sheet Requirements
A1: รหัส | B1: ข้อกำหนด | C1: ความสำคัญ | D1: จำนวน Test Case
A2: FR-01 | B2: เข้าสู่ระบบด้วย @ku.th + OTP ครั้งแรก ตั้งรหัสผ่าน reset/logout/session หมดอายุ | C2: สูง | D2: =COUNTIF('Test Cases'!$B:$B,A2)
A3: FR-02 | B3: แจ้งของหาย ระบุประเภท ยี่ห้อ/รุ่น ลักษณะเฉพาะ วันเวลา สถานที่ สี แนบภาพ | C3: สูง | D3: =COUNTIF('Test Cases'!$B:$B,A3)
A4: FR-03 | B4: แจ้งของพบ ระบุจุดฝาก เจ้าหน้าที่อัปเดตจุดฝากได้ | C4: สูง | D4: =COUNTIF('Test Cases'!$B:$B,A4)
A5: FR-04 | B5: จับคู่อัตโนมัติจากประเภท สี สถานที่ ช่วงเวลา พร้อม confidence score | C5: สูง | D5: =COUNTIF('Test Cases'!$B:$B,A5)
A6: FR-05 | B6: แจ้งเตือนทั้งสองฝ่ายเมื่อพบคู่ (อีเมล / in-app) | C6: สูง | D6: =COUNTIF('Test Cases'!$B:$B,A6)
A7: FR-06 | B7: ปกปิดลักษณะเฉพาะจากรายการทั่วไป | C7: สูง | D7: =COUNTIF('Test Cases'!$B:$B,A7)
A8: FR-07 | B8: ขอรับคืน ตอบลักษณะเฉพาะ เจ้าหน้าที่ตรวจก่อนส่งมอบ | C8: สูง | D8: =COUNTIF('Test Cases'!$B:$B,A8)
A9: FR-08 | B9: ติดตามสถานะรายงานของตนเอง | C9: กลาง | D9: =COUNTIF('Test Cases'!$B:$B,A9)
A10: FR-09 | B10: แสดงจุดฝาก แผนที่ และเวลาทำการ | C10: กลาง | D10: =COUNTIF('Test Cases'!$B:$B,A10)
A11: FR-10 | B11: เจ้าหน้าที่รับฝาก ย้ายจุด ส่งคืน จำหน่าย/บริจาค | C11: กลาง | D11: =COUNTIF('Test Cases'!$B:$B,A11)
A12: FR-11 | B12: กำหนดระยะเก็บ แจ้งเตือนก่อนครบกำหนด | C12: กลาง | D12: =COUNTIF('Test Cases'!$B:$B,A12)
A13: FR-12 | B13: ค้นหาและกรองตามประเภท วันที่ สถานที่ สถานะ | C13: กลาง | D13: =COUNTIF('Test Cases'!$B:$B,A13)
... A17: NFR | B17: Security, PDPA, Performance, Usability, Localization | C17: — | D17: =COUNTIF('Test Cases'!$B:$B,A17)

Sheet หลักฐานการทดสอบ
A1: หลักฐานและวิธีทดสอบ
A3: ขอบเขต | B3: รันทั้ง 82 กรณีในชีต Test Cases วันที่ 25 ต.ค. 2569 บนเครื่อง Windows 10 ของผู้ใช้
A4: สภาพแวดล้อม | B4: ฐานข้อมูล PostgreSQL จำลองในหน่วยความจำ (PGlite) แยกจากฐานจริง; ดักอีเมลไว้ ไม่ส่งออกจริง; ไม่แตะข้อมูล รูป หรือบัญชีจริง
A5: วิธีทดสอบ API (75 กรณี) | B5: สคริปต์ Node เรียก HTTP API ตามขั้นตอนของแต่ละกรณี แล้วตรวจ status code, response และข้อมูลในฐาน
A6: วิธีทดสอบหน้าเว็บ (7 กรณี) | B6: Playwright บน Microsoft Edge: TC-FR01-14 และ TC-NFR-05 ทดสอบตรง (มีภาพหน้าจอ); TC-NFR-01/02/03 อ้างผล e2e ของโปรเจกต์
A7: ชุด unit/integration ของโปรเจกต์ | B7: npm run test:unit — 302 tests: ผ่าน 295, ล้มเหลว 0, ข้าม 2, TODO (บั๊กที่รู้แล้ว) 5
A8: ชุด e2e ของโปรเจกต์ | B8: npx playwright test — ผ่าน 178/178 (6.8 นาที)
A9: บั๊ก TODO ที่โปรเจกต์บันทึกไว้ | B9: BUG-01: ส่งรูปผิดชื่อฟิลด์/หลายรูปได้ HTTP 500 แทน 4xx; BUG-02: รับวันที่ในอนาคต; BUG-03: อักขระ % และ _ ในช่องค้นหาไม่ถูก escape
A10: ข้อจำกัด | B10: ไม่ได้ทดสอบ: ส่งอีเมลจริง, Google OAuth จริง, โมเดล vision จริง, HTTPS บน production, โหลด 500 คน, uptime 99%, screen reader โดยคน
A11: รอบ 2 — ทดสอบซ้ำหลังแก้ BUG-02 | B11: แก้: ปฏิเสธวันที่หาย/พบในอนาคต (backend) + ตั้ง max ให้ช่องวันที่ (ฟอร์ม). รันซ้ำทั้ง 75 กรณี API: ผลเดิมทุกข้อ ยกเว้น TC-FR02-08 เปลี่ยนเป็น Pass. ชุด unit: 302 tests ผ่าน 296 ล้มเหลว 0 (API-ITEM-10 ผ่านแล้ว). e2e ฟอร์มแจ้ง/claim/matching: ผ่าน 64/64. build ผ่าน
A12: รอบ 3 — ทดสอบซ้ำหลังแก้ TC-FR06-02 | B12: แก้: เจ้าของดูลักษณะเฉพาะที่ตนกรอกได้ในหน้าประวัติของฉัน. รันซ้ำ 75 กรณี API: ผลเดิมทุกข้อ ยกเว้น TC-FR06-02 เปลี่ยนเป็น Pass. ชุด unit: 303 tests ผ่าน 297 ล้มเหลว 0 (เพิ่ม API-HIST-02). e2e: ผ่าน 75/75 (เพิ่ม history-private-details.spec รวม visual snapshot, accessibility, localization). build ผ่าน
A13: รอบ 4 — ทดสอบซ้ำหลังแก้ TC-FR05-01 | B13: แก้: ส่งอีเมลแจ้งทั้งสองฝ่ายเมื่อระบบพบคู่. รันซ้ำ 75 กรณี API: ผลเดิมทุกข้อ ยกเว้น TC-FR05-01 เปลี่ยนเป็น Pass. ชุด unit: 304 tests ผ่าน 298 ล้มเหลว 0 (เพิ่ม test อีเมลแจ้งคู่ใน matching.test.cjs). e2e จับคู่/แจ้งเตือน/admin/ฟอร์ม: ผ่าน 46/46
A14: รอบ 5 — แก้ผลที่คาดหวัง TC-FR01-03 | B14: เจ้าของโปรเจกต์ยืนยันให้คงข้อความแจ้งชัด จึงเปลี่ยนผลที่คาดหวังของ TC-FR01-03 (ทั้งไฟล์ template และไฟล์ผล) แล้วรันซ้ำทั้ง 75 กรณี API: ผ่านทั้งหมด
